Workbook

Sheet How to use
B2: Yontro Founder File - CONFIDENTIAL
B4: CONFIDENTIAL: share with Sahill Chandan only. Do not share this file with any employee. In Google Sheets: Share > Restricted, no other people added.
B6: Tabs:
B7: Sales Daily KPIs - one row per rep per working day. Targets: 100 calls and outreaches, 4 meetings booked for the next day, 2 meetings done, all pipeline follow-ups cleared.
B8: Sales Weekly KPIs - weekly totals per rep, including closed deals (target 2 a week). Calculated from the daily tab.
B9: Spending - every business expense. Earnings - every invoice and payment received.
B10: Monthly Summary - invoiced, received, spent, profit and margin per month. Calculated.
B11: Growth Targets - target clients and revenue per month, driven by the number of sales reps and the settings.
B12: Hiring Plan - team needed per month for the target clients, hires needed, payroll vs revenue.
B13: Scaling Milestones - the trigger for each hire or expansion step, and the month the targets reach it.
B14: Settings - every target and assumption the formulas use. Change them here only.
B16: Where the daily sales numbers come from: each rep sends their numbers to Sahill on WhatsApp at 19:00; Sahill (or a person he names) enters them. Follow-ups due come from the Pipeline file's Summary tab.
... B21: Grey italic row 2 on each tab = EXAMPLE showing the format. Delete it once real data starts.

Sheet Sales Daily KPIs
A1: Date | B1: Sales rep | C1: Calls and outreaches (target 100) | D1: Meetings booked for next day (target 4) | E1: Meetings done today (target 2) | F1: Follow-ups due from pipeline | G1: Follow-ups done | H1: Follow-ups cleared % | I1: Deals closed today | J1: Daily targets hit (of 4) | K1: Notes / what stopped the target
A2: 46344 | B2: Usama Rehman | C2: 104 | D2: 4 | E2: 2 | F2: 6 | G2: 6 | H2: =IF(OR(F2="",F2=0),IF(G2="","",1),MIN(1,G2/F2)) -> 1 | I2: 0 | J2: =IF(C2="","",(C2>=Settings!$B$2)+(D2>=Settings!$B$3)+(E2>=Settings!$B$4)+(N(H2)>=1))&"/4" -> 4/4 | K2: EXAMPLE row - delete
A3: 46345 | B3: Usama Rehman | H3: =IF(OR(F3="",F3=0),IF(G3="","",1),MIN(1,G3/F3)) | J3: =IF(C3="","",(C3>=Settings!$B$2)+(D3>=Settings!$B$3)+(E3>=Settings!$B$4)+(N(H3)>=1))&"/4" -> /4
A4: 46346 | B4: Usama Rehman | H4: =IF(OR(F4="",F4=0),IF(G4="","",1),MIN(1,G4/F4)) | J4: =IF(C4="","",(C4>=Settings!$B$2)+(D4>=Settings!$B$3)+(E4>=Settings!$B$4)+(N(H4)>=1))&"/4" -> /4
A5: 46347 | B5: Usama Rehman | H5: =IF(OR(F5="",F5=0),IF(G5="","",1),MIN(1,G5/F5)) | J5: =IF(C5="","",(C5>=Settings!$B$2)+(D5>=Settings!$B$3)+(E5>=Settings!$B$4)+(N(H5)>=1))&"/4" -> /4
A6: 46349 | B6: Usama Rehman | H6: =IF(OR(F6="",F6=0),IF(G6="","",1),MIN(1,G6/F6)) | J6: =IF(C6="","",(C6>=Settings!$B$2)+(D6>=Settings!$B$3)+(E6>=Settings!$B$4)+(N(H6)>=1))&"/4" -> /4
A7: 46350 | B7: Usama Rehman | H7: =IF(OR(F7="",F7=0),IF(G7="","",1),MIN(1,G7/F7)) | J7: =IF(C7="","",(C7>=Settings!$B$2)+(D7>=Settings!$B$3)+(E7>=Settings!$B$4)+(N(H7)>=1))&"/4" -> /4
A8: 46351 | B8: Usama Rehman | H8: =IF(OR(F8="",F8=0),IF(G8="","",1),MIN(1,G8/F8)) | J8: =IF(C8="","",(C8>=Settings!$B$2)+(D8>=Settings!$B$3)+(E8>=Settings!$B$4)+(N(H8)>=1))&"/4" -> /4
A9: 46352 | B9: Usama Rehman | H9: =IF(OR(F9="",F9=0),IF(G9="","",1),MIN(1,G9/F9)) | J9: =IF(C9="","",(C9>=Settings!$B$2)+(D9>=Settings!$B$3)+(E9>=Settings!$B$4)+(N(H9)>=1))&"/4" -> /4
A10: 46353 | B10: Usama Rehman | H10: =IF(OR(F10="",F10=0),IF(G10="","",1),MIN(1,G10/F10)) | J10: =IF(C10="","",(C10>=Settings!$B$2)+(D10>=Settings!$B$3)+(E10>=Settings!$B$4)+(N(H10)>=1))&"/4" -> /4
A11: 46354 | B11: Usama Rehman | H11: =IF(OR(F11="",F11=0),IF(G11="","",1),MIN(1,G11/F11)) | J11: =IF(C11="","",(C11>=Settings!$B$2)+(D11>=Settings!$B$3)+(E11>=Settings!$B$4)+(N(H11)>=1))&"/4" -> /4
A12: 46356 | B12: Usama Rehman | H12: =IF(OR(F12="",F12=0),IF(G12="","",1),MIN(1,G12/F12)) | J12: =IF(C12="","",(C12>=Settings!$B$2)+(D12>=Settings!$B$3)+(E12>=Settings!$B$4)+(N(H12)>=1))&"/4" -> /4
A13: 46357 | B13: Usama Rehman | H13: =IF(OR(F13="",F13=0),IF(G13="","",1),MIN(1,G13/F13)) | J13: =IF(C13="","",(C13>=Settings!$B$2)+(D13>=Settings!$B$3)+(E13>=Settings!$B$4)+(N(H13)>=1))&"/4" -> /4
A14: 46358 | B14: Usama Rehman | H14: =IF(OR(F14="",F14=0),IF(G14="","",1),MIN(1,G14/F14)) | J14: =IF(C14="","",(C14>=Settings!$B$2)+(D14>=Settings!$B$3)+(E14>=Settings!$B$4)+(N(H14)>=1))&"/4" -> /4
... A39: 46387 | B39: Usama Rehman | H39: =IF(OR(F39="",F39=0),IF(G39="","",1),MIN(1,G39/F39)) | J39: =IF(C39="","",(C39>=Settings!$B$2)+(D39>=Settings!$B$3)+(E39>=Settings!$B$4)+(N(H39)>=1))&"/4" -> /4
H40: =IF(OR(F40="",F40=0),IF(G40="","",1),MIN(1,G40/F40)) | J40: =IF(C40="","",(C40>=Settings!$B$2)+(D40>=Settings!$B$3)+(E40>=Settings!$B$4)+(N(H40)>=1))&"/4" -> /4
H41: =IF(OR(F41="",F41=0),IF(G41="","",1),MIN(1,G41/F41)) | J41: =IF(C41="","",(C41>=Settings!$B$2)+(D41>=Settings!$B$3)+(E41>=Settings!$B$4)+(N(H41)>=1))&"/4" -> /4
H42: =IF(OR(F42="",F42=0),IF(G42="","",1),MIN(1,G42/F42)) | J42: =IF(C42="","",(C42>=Settings!$B$2)+(D42>=Settings!$B$3)+(E42>=Settings!$B$4)+(N(H42)>=1))&"/4" -> /4
H43: =IF(OR(F43="",F43=0),IF(G43="","",1),MIN(1,G43/F43)) | J43: =IF(C43="","",(C43>=Settings!$B$2)+(D43>=Settings!$B$3)+(E43>=Settings!$B$4)+(N(H43)>=1))&"/4" -> /4
H44: =IF(OR(F44="",F44=0),IF(G44="","",1),MIN(1,G44/F44)) | J44: =IF(C44="","",(C44>=Settings!$B$2)+(D44>=Settings!$B$3)+(E44>=Settings!$B$4)+(N(H44)>=1))&"/4" -> /4
H45: =IF(OR(F45="",F45=0),IF(G45="","",1),MIN(1,G45/F45)) | J45: =IF(C45="","",(C45>=Settings!$B$2)+(D45>=Settings!$B$3)+(E45>=Settings!$B$4)+(N(H45)>=1))&"/4" -> /4
H46: =IF(OR(F46="",F46=0),IF(G46="","",1),MIN(1,G46/F46)) | J46: =IF(C46="","",(C46>=Settings!$B$2)+(D46>=Settings!$B$3)+(E46>=Settings!$B$4)+(N(H46)>=1))&"/4" -> /4
H47: =IF(OR(F47="",F47=0),IF(G47="","",1),MIN(1,G47/F47)) | J47: =IF(C47="","",(C47>=Settings!$B$2)+(D47>=Settings!$B$3)+(E47>=Settings!$B$4)+(N(H47)>=1))&"/4" -> /4
H48: =IF(OR(F48="",F48=0),IF(G48="","",1),MIN(1,G48/F48)) | J48: =IF(C48="","",(C48>=Settings!$B$2)+(D48>=Settings!$B$3)+(E48>=Settings!$B$4)+(N(H48)>=1))&"/4" -> /4
H49: =IF(OR(F49="",F49=0),IF(G49="","",1),MIN(1,G49/F49)) | J49: =IF(C49="","",(C49>=Settings!$B$2)+(D49>=Settings!$B$3)+(E49>=Settings!$B$4)+(N(H49)>=1))&"/4" -> /4
H50: =IF(OR(F50="",F50=0),IF(G50="","",1),MIN(1,G50/F50)) | J50: =IF(C50="","",(C50>=Settings!$B$2)+(D50>=Settings!$B$3)+(E50>=Settings!$B$4)+(N(H50)>=1))&"/4" -> /4
H51: =IF(OR(F51="",F51=0),IF(G51="","",1),MIN(1,G51/F51)) | J51: =IF(C51="","",(C51>=Settings!$B$2)+(D51>=Settings!$B$3)+(E51>=Settings!$B$4)+(N(H51)>=1))&"/4" -> /4
... H601: =IF(OR(F601="",F601=0),IF(G601="","",1),MIN(1,G601/F601)) | J601: =IF(C601="","",(C601>=Settings!$B$2)+(D601>=Settings!$B$3)+(E601>=Settings!$B$4)+(N(H601)>=1))&"/4" -> /4

Sheet Sales Weekly KPIs
A1: Week start | B1: Week end | C1: Sales rep | D1: Days reported | E1: Calls and outreaches | F1: Target | G1: Meetings booked | H1: Target | I1: Meetings done | J1: Target | K1: Follow-ups cleared % | L1: Deals closed | M1: Target | N1: Notes
A2: 46345 | B2: =IF(A2="","",A2+6) -> 46351 | C2: Usama Rehman | D2: =IF(A2="","",COUNTIFS('Sales Daily KPIs'!$B:$B,$C2,'Sales Daily KPIs'!$A:$A,">="&$A2,'Sales Daily KPIs'!$A:$A,"<="&$B2,'Sales Daily KPIs'!$C:$C,"<>")) -> 0 | E2: =IF(A2="","",SUMIFS('Sales Daily KPIs'!$C:$C,'Sales Daily KPIs'!$B:$B,$C2,'Sales Daily KPIs'!$A:$A,">="&$A2,'Sales Daily KPIs'!$A:$A,"<="&$B2)) -> 0 | F2: =IF(A2="","",Settings!$B$2*Settings!$B$6) -> 600 | G2: =IF(A2="","",SUMIFS('Sales Daily KPIs'!$D:$D,'Sales Daily KPIs'!$B:$B,$C2,'Sales Daily KPIs'!$A:$A,">="&$A2,'Sales Daily KPIs'!$A:$A,"<="&$B2)) -> 0 | H2: =IF(A2="","",Settings!$B$3*Settings!$B$6) -> 24 | I2: =IF(A2="","",SUMIFS('Sales Daily KPIs'!$E:$E,'Sales Daily KPIs'!$B:$B,$C2,'Sales Daily KPIs'!$A:$A,">="&$A2,'Sales Daily KPIs'!$A:$A,"<="&$B2)) -> 0 | J2: =IF(A2="","",Settings!$B$4*Settings!$B$6) -> 12 | K2: =IF(A2="","",IFERROR(SUMIFS('Sales Daily KPIs'!$G:$G,'Sales Daily KPIs'!$B:$B,$C2,'Sales Daily KPIs'!$A:$A,">="&$A2,'Sales Daily KPIs'!$A:$A,"<="&$B2)/SUMIFS('Sales Daily KPIs'!$F:$F,'Sales Daily KPIs'!$B:$B,$C2,'Sales Daily KPIs'!$A:$A,">="&$A2,'Sales Daily KPIs'!$A:$A,"<="&$B2),"")) | L2: =IF(A2="","",SUMIFS('Sales Daily KPIs'!$I:$I,'Sales Daily KPIs'!$B:$B,$C2,'Sales Daily KPIs'!$A:$A,">="&$A2,'Sales Daily KPIs'!$A:$A,"<="&$B2)) -> 0 | M2: =IF(A2="","",Settings!$B$5) -> 2
A3: 46352 | B3: =IF(A3="","",A3+6) -> 46358 | C3: Usama Rehman | D3: =IF(A3="","",COUNTIFS('Sales Daily KPIs'!$B:$B,$C3,'Sales Daily KPIs'!$A:$A,">="&$A3,'Sales Daily KPIs'!$A:$A,"<="&$B3,'Sales Daily KPIs'!$C:$C,"<>")) -> 0 | E3: =IF(A3="","",SUMIFS('Sales Daily KPIs'!$C:$C,'Sales Daily KPIs'!$B:$B,$C3,'Sales Daily KPIs'!$A:$A,">="&$A3,'Sales Daily KPIs'!$A:$A,"<="&$B3)) -> 0 | F3: =IF(A3="","",Settings!$B$2*Settings!$B$6) -> 600 | G3: =IF(A3="","",SUMIFS('Sales Daily KPIs'!$D:$D,'Sales Daily KPIs'!$B:$B,$C3,'Sales Daily KPIs'!$A:$A,">="&$A3,'Sales Daily KPIs'!$A:$A,"<="&$B3)) -> 0 | H3: =IF(A3="","",Settings!$B$3*Settings!$B$6) -> 24 | I3: =IF(A3="","",SUMIFS('Sales Daily KPIs'!$E:$E,'Sales Daily KPIs'!$B:$B,$C3,'Sales Daily KPIs'!$A:$A,">="&$A3,'Sales Daily KPIs'!$A:$A,"<="&$B3)) -> 0 | J3: =IF(A3="","",Settings!$B$4*Settings!$B$6) -> 12 | K3: =IF(A3="","",IFERROR(SUMIFS('Sales Daily KPIs'!$G:$G,'Sales Daily KPIs'!$B:$B,$C3,'Sales Daily KPIs'!$A:$A,">="&$A3,'Sales Daily KPIs'!$A:$A,"<="&$B3)/SUMIFS('Sales Daily KPIs'!$F:$F,'Sales Daily KPIs'!$B:$B,$C3,'Sales Daily KPIs'!$A:$A,">="&$A3,'Sales Daily KPIs'!$A:$A,"<="&$B3),"")) | L3: =IF(A3="","",SUMIFS('Sales Daily KPIs'!$I:$I,'Sales Daily KPIs'!$B:$B,$C3,'Sales Daily KPIs'!$A:$A,">="&$A3,'Sales Daily KPIs'!$A:$A,"<="&$B3)) -> 0 | M3: =IF(A3="","",Settings!$B$5) -> 2
A4: 46359 | B4: =IF(A4="","",A4+6) -> 46365 | C4: Usama Rehman | D4: =IF(A4="","",COUNTIFS('Sales Daily KPIs'!$B:$B,$C4,'Sales Daily KPIs'!$A:$A,">="&$A4,'Sales Daily KPIs'!$A:$A,"<="&$B4,'Sales Daily KPIs'!$C:$C,"<>")) -> 0 | E4: =IF(A4="","",SUMIFS('Sales Daily KPIs'!$C:$C,'Sales Daily KPIs'!$B:$B,$C4,'Sales Daily KPIs'!$A:$A,">="&$A4,'Sales Daily KPIs'!$A:$A,"<="&$B4)) -> 0 | F4: =IF(A4="","",Settings!$B$2*Settings!$B$6) -> 600 | G4: =IF(A4="","",SUMIFS('Sales Daily KPIs'!$D:$D,'Sales Daily KPIs'!$B:$B,$C4,'Sales Daily KPIs'!$A:$A,">="&$A4,'Sales Daily KPIs'!$A:$A,"<="&$B4)) -> 0 | H4: =IF(A4="","",Settings!$B$3*Settings!$B$6) -> 24 | I4: =IF(A4="","",SUMIFS('Sales Daily KPIs'!$E:$E,'Sales Daily KPIs'!$B:$B,$C4,'Sales Daily KPIs'!$A:$A,">="&$A4,'Sales Daily KPIs'!$A:$A,"<="&$B4)) -> 0 | J4: =IF(A4="","",Settings!$B$4*Settings!$B$6) -> 12 | K4: =IF(A4="","",IFERROR(SUMIFS('Sales Daily KPIs'!$G:$G,'Sales Daily KPIs'!$B:$B,$C4,'Sales Daily KPIs'!$A:$A,">="&$A4,'Sales Daily KPIs'!$A:$A,"<="&$B4)/SUMIFS('Sales Daily KPIs'!$F:$F,'Sales Daily KPIs'!$B:$B,$C4,'Sales Daily KPIs'!$A:$A,">="&$A4,'Sales Daily KPIs'!$A:$A,"<="&$B4),"")) | L4: =IF(A4="","",SUMIFS('Sales Daily KPIs'!$I:$I,'Sales Daily KPIs'!$B:$B,$C4,'Sales Daily KPIs'!$A:$A,">="&$A4,'Sales Daily KPIs'!$A:$A,"<="&$B4)) -> 0 | M4: =IF(A4="","",Settings!$B$5) -> 2
A5: 46366 | B5: =IF(A5="","",A5+6) -> 46372 | C5: Usama Rehman | D5: =IF(A5="","",COUNTIFS('Sales Daily KPIs'!$B:$B,$C5,'Sales Daily KPIs'!$A:$A,">="&$A5,'Sales Daily KPIs'!$A:$A,"<="&$B5,'Sales Daily KPIs'!$C:$C,"<>")) -> 0 | E5: =IF(A5="","",SUMIFS('Sales Daily KPIs'!$C:$C,'Sales Daily KPIs'!$B:$B,$C5,'Sales Daily KPIs'!$A:$A,">="&$A5,'Sales Daily KPIs'!$A:$A,"<="&$B5)) -> 0 | F5: =IF(A5="","",Settings!$B$2*Settings!$B$6) -> 600 | G5: =IF(A5="","",SUMIFS('Sales Daily KPIs'!$D:$D,'Sales Daily KPIs'!$B:$B,$C5,'Sales Daily KPIs'!$A:$A,">="&$A5,'Sales Daily KPIs'!$A:$A,"<="&$B5)) -> 0 | H5: =IF(A5="","",Settings!$B$3*Settings!$B$6) -> 24 | I5: =IF(A5="","",SUMIFS('Sales Daily KPIs'!$E:$E,'Sales Daily KPIs'!$B:$B,$C5,'Sales Daily KPIs'!$A:$A,">="&$A5,'Sales Daily KPIs'!$A:$A,"<="&$B5)) -> 0 | J5: =IF(A5="","",Settings!$B$4*Settings!$B$6) -> 12 | K5: =IF(A5="","",IFERROR(SUMIFS('Sales Daily KPIs'!$G:$G,'Sales Daily KPIs'!$B:$B,$C5,'Sales Daily KPIs'!$A:$A,">="&$A5,'Sales Daily KPIs'!$A:$A,"<="&$B5)/SUMIFS('Sales Daily KPIs'!$F:$F,'Sales Daily KPIs'!$B:$B,$C5,'Sales Daily KPIs'!$A:$A,">="&$A5,'Sales Daily KPIs'!$A:$A,"<="&$B5),"")) | L5: =IF(A5="","",SUMIFS('Sales Daily KPIs'!$I:$I,'Sales Daily KPIs'!$B:$B,$C5,'Sales Daily KPIs'!$A:$A,">="&$A5,'Sales Daily KPIs'!$A:$A,"<="&$B5)) -> 0 | M5: =IF(A5="","",Settings!$B$5) -> 2
A6: 46373 | B6: =IF(A6="","",A6+6) -> 46379 | C6: Usama Rehman | D6: =IF(A6="","",COUNTIFS('Sales Daily KPIs'!$B:$B,$C6,'Sales Daily KPIs'!$A:$A,">="&$A6,'Sales Daily KPIs'!$A:$A,"<="&$B6,'Sales Daily KPIs'!$C:$C,"<>")) -> 0 | E6: =IF(A6="","",SUMIFS('Sales Daily KPIs'!$C:$C,'Sales Daily KPIs'!$B:$B,$C6,'Sales Daily KPIs'!$A:$A,">="&$A6,'Sales Daily KPIs'!$A:$A,"<="&$B6)) -> 0 | F6: =IF(A6="","",Settings!$B$2*Settings!$B$6) -> 600 | G6: =IF(A6="","",SUMIFS('Sales Daily KPIs'!$D:$D,'Sales Daily KPIs'!$B:$B,$C6,'Sales Daily KPIs'!$A:$A,">="&$A6,'Sales Daily KPIs'!$A:$A,"<="&$B6)) -> 0 | H6: =IF(A6="","",Settings!$B$3*Settings!$B$6) -> 24 | I6: =IF(A6="","",SUMIFS('Sales Daily KPIs'!$E:$E,'Sales Daily KPIs'!$B:$B,$C6,'Sales Daily KPIs'!$A:$A,">="&$A6,'Sales Daily KPIs'!$A:$A,"<="&$B6)) -> 0 | J6: =IF(A6="","",Settings!$B$4*Settings!$B$6) -> 12 | K6: =IF(A6="","",IFERROR(SUMIFS('Sales Daily KPIs'!$G:$G,'Sales Daily KPIs'!$B:$B,$C6,'Sales Daily KPIs'!$A:$A,">="&$A6,'Sales Daily KPIs'!$A:$A,"<="&$B6)/SUMIFS('Sales Daily KPIs'!$F:$F,'Sales Daily KPIs'!$B:$B,$C6,'Sales Daily KPIs'!$A:$A,">="&$A6,'Sales Daily KPIs'!$A:$A,"<="&$B6),"")) | L6: =IF(A6="","",SUMIFS('Sales Daily KPIs'!$I:$I,'Sales Daily KPIs'!$B:$B,$C6,'Sales Daily KPIs'!$A:$A,">="&$A6,'Sales Daily KPIs'!$A:$A,"<="&$B6)) -> 0 | M6: =IF(A6="","",Settings!$B$5) -> 2
A7: 46380 | B7: =IF(A7="","",A7+6) -> 46386 | C7: Usama Rehman | D7: =IF(A7="","",COUNTIFS('Sales Daily KPIs'!$B:$B,$C7,'Sales Daily KPIs'!$A:$A,">="&$A7,'Sales Daily KPIs'!$A:$A,"<="&$B7,'Sales Daily KPIs'!$C:$C,"<>")) -> 0 | E7: =IF(A7="","",SUMIFS('Sales Daily KPIs'!$C:$C,'Sales Daily KPIs'!$B:$B,$C7,'Sales Daily KPIs'!$A:$A,">="&$A7,'Sales Daily KPIs'!$A:$A,"<="&$B7)) -> 0 | F7: =IF(A7="","",Settings!$B$2*Settings!$B$6) -> 600 | G7: =IF(A7="","",SUMIFS('Sales Daily KPIs'!$D:$D,'Sales Daily KPIs'!$B:$B,$C7,'Sales Daily KPIs'!$A:$A,">="&$A7,'Sales Daily KPIs'!$A:$A,"<="&$B7)) -> 0 | H7: =IF(A7="","",Settings!$B$3*Settings!$B$6) -> 24 | I7: =IF(A7="","",SUMIFS('Sales Daily KPIs'!$E:$E,'Sales Daily KPIs'!$B:$B,$C7,'Sales Daily KPIs'!$A:$A,">="&$A7,'Sales Daily KPIs'!$A:$A,"<="&$B7)) -> 0 | J7: =IF(A7="","",Settings!$B$4*Settings!$B$6) -> 12 | K7: =IF(A7="","",IFERROR(SUMIFS('Sales Daily KPIs'!$G:$G,'Sales Daily KPIs'!$B:$B,$C7,'Sales Daily KPIs'!$A:$A,">="&$A7,'Sales Daily KPIs'!$A:$A,"<="&$B7)/SUMIFS('Sales Daily KPIs'!$F:$F,'Sales Daily KPIs'!$B:$B,$C7,'Sales Daily KPIs'!$A:$A,">="&$A7,'Sales Daily KPIs'!$A:$A,"<="&$B7),"")) | L7: =IF(A7="","",SUMIFS('Sales Daily KPIs'!$I:$I,'Sales Daily KPIs'!$B:$B,$C7,'Sales Daily KPIs'!$A:$A,">="&$A7,'Sales Daily KPIs'!$A:$A,"<="&$B7)) -> 0 | M7: =IF(A7="","",Settings!$B$5) -> 2
A8: 46387 | B8: =IF(A8="","",A8+6) -> 46393 | C8: Usama Rehman | D8: =IF(A8="","",COUNTIFS('Sales Daily KPIs'!$B:$B,$C8,'Sales Daily KPIs'!$A:$A,">="&$A8,'Sales Daily KPIs'!$A:$A,"<="&$B8,'Sales Daily KPIs'!$C:$C,"<>")) -> 0 | E8: =IF(A8="","",SUMIFS('Sales Daily KPIs'!$C:$C,'Sales Daily KPIs'!$B:$B,$C8,'Sales Daily KPIs'!$A:$A,">="&$A8,'Sales Daily KPIs'!$A:$A,"<="&$B8)) -> 0 | F8: =IF(A8="","",Settings!$B$2*Settings!$B$6) -> 600 | G8: =IF(A8="","",SUMIFS('Sales Daily KPIs'!$D:$D,'Sales Daily KPIs'!$B:$B,$C8,'Sales Daily KPIs'!$A:$A,">="&$A8,'Sales Daily KPIs'!$A:$A,"<="&$B8)) -> 0 | H8: =IF(A8="","",Settings!$B$3*Settings!$B$6) -> 24 | I8: =IF(A8="","",SUMIFS('Sales Daily KPIs'!$E:$E,'Sales Daily KPIs'!$B:$B,$C8,'Sales Daily KPIs'!$A:$A,">="&$A8,'Sales Daily KPIs'!$A:$A,"<="&$B8)) -> 0 | J8: =IF(A8="","",Settings!$B$4*Settings!$B$6) -> 12 | K8: =IF(A8="","",IFERROR(SUMIFS('Sales Daily KPIs'!$G:$G,'Sales Daily KPIs'!$B:$B,$C8,'Sales Daily KPIs'!$A:$A,">="&$A8,'Sales Daily KPIs'!$A:$A,"<="&$B8)/SUMIFS('Sales Daily KPIs'!$F:$F,'Sales Daily KPIs'!$B:$B,$C8,'Sales Daily KPIs'!$A:$A,">="&$A8,'Sales Daily KPIs'!$A:$A,"<="&$B8),"")) | L8: =IF(A8="","",SUMIFS('Sales Daily KPIs'!$I:$I,'Sales Daily KPIs'!$B:$B,$C8,'Sales Daily KPIs'!$A:$A,">="&$A8,'Sales Daily KPIs'!$A:$A,"<="&$B8)) -> 0 | M8: =IF(A8="","",Settings!$B$5) -> 2
A9: 46394 | B9: =IF(A9="","",A9+6) -> 46400 | C9: Usama Rehman | D9: =IF(A9="","",COUNTIFS('Sales Daily KPIs'!$B:$B,$C9,'Sales Daily KPIs'!$A:$A,">="&$A9,'Sales Daily KPIs'!$A:$A,"<="&$B9,'Sales Daily KPIs'!$C:$C,"<>")) -> 0 | E9: =IF(A9="","",SUMIFS('Sales Daily KPIs'!$C:$C,'Sales Daily KPIs'!$B:$B,$C9,'Sales Daily KPIs'!$A:$A,">="&$A9,'Sales Daily KPIs'!$A:$A,"<="&$B9)) -> 0 | F9: =IF(A9="","",Settings!$B$2*Settings!$B$6) -> 600 | G9: =IF(A9="","",SUMIFS('Sales Daily KPIs'!$D:$D,'Sales Daily KPIs'!$B:$B,$C9,'Sales Daily KPIs'!$A:$A,">="&$A9,'Sales Daily KPIs'!$A:$A,"<="&$B9)) -> 0 | H9: =IF(A9="","",Settings!$B$3*Settings!$B$6) -> 24 | I9: =IF(A9="","",SUMIFS('Sales Daily KPIs'!$E:$E,'Sales Daily KPIs'!$B:$B,$C9,'Sales Daily KPIs'!$A:$A,">="&$A9,'Sales Daily KPIs'!$A:$A,"<="&$B9)) -> 0 | J9: =IF(A9="","",Settings!$B$4*Settings!$B$6) -> 12 | K9: =IF(A9="","",IFERROR(SUMIFS('Sales Daily KPIs'!$G:$G,'Sales Daily KPIs'!$B:$B,$C9,'Sales Daily KPIs'!$A:$A,">="&$A9,'Sales Daily KPIs'!$A:$A,"<="&$B9)/SUMIFS('Sales Daily KPIs'!$F:$F,'Sales Daily KPIs'!$B:$B,$C9,'Sales Daily KPIs'!$A:$A,">="&$A9,'Sales Daily KPIs'!$A:$A,"<="&$B9),"")) | L9: =IF(A9="","",SUMIFS('Sales Daily KPIs'!$I:$I,'Sales Daily KPIs'!$B:$B,$C9,'Sales Daily KPIs'!$A:$A,">="&$A9,'Sales Daily KPIs'!$A:$A,"<="&$B9)) -> 0 | M9: =IF(A9="","",Settings!$B$5) -> 2
A10: 46401 | B10: =IF(A10="","",A10+6) -> 46407 | C10: Usama Rehman | D10: =IF(A10="","",COUNTIFS('Sales Daily KPIs'!$B:$B,$C10,'Sales Daily KPIs'!$A:$A,">="&$A10,'Sales Daily KPIs'!$A:$A,"<="&$B10,'Sales Daily KPIs'!$C:$C,"<>")) -> 0 | E10: =IF(A10="","",SUMIFS('Sales Daily KPIs'!$C:$C,'Sales Daily KPIs'!$B:$B,$C10,'Sales Daily KPIs'!$A:$A,">="&$A10,'Sales Daily KPIs'!$A:$A,"<="&$B10)) -> 0 | F10: =IF(A10="","",Settings!$B$2*Settings!$B$6) -> 600 | G10: =IF(A10="","",SUMIFS('Sales Daily KPIs'!$D:$D,'Sales Daily KPIs'!$B:$B,$C10,'Sales Daily KPIs'!$A:$A,">="&$A10,'Sales Daily KPIs'!$A:$A,"<="&$B10)) -> 0 | H10: =IF(A10="","",Settings!$B$3*Settings!$B$6) -> 24 | I10: =IF(A10="","",SUMIFS('Sales Daily KPIs'!$E:$E,'Sales Daily KPIs'!$B:$B,$C10,'Sales Daily KPIs'!$A:$A,">="&$A10,'Sales Daily KPIs'!$A:$A,"<="&$B10)) -> 0 | J10: =IF(A10="","",Settings!$B$4*Settings!$B$6) -> 12 | K10: =IF(A10="","",IFERROR(SUMIFS('Sales Daily KPIs'!$G:$G,'Sales Daily KPIs'!$B:$B,$C10,'Sales Daily KPIs'!$A:$A,">="&$A10,'Sales Daily KPIs'!$A:$A,"<="&$B10)/SUMIFS('Sales Daily KPIs'!$F:$F,'Sales Daily KPIs'!$B:$B,$C10,'Sales Daily KPIs'!$A:$A,">="&$A10,'Sales Daily KPIs'!$A:$A,"<="&$B10),"")) | L10: =IF(A10="","",SUMIFS('Sales Daily KPIs'!$I:$I,'Sales Daily KPIs'!$B:$B,$C10,'Sales Daily KPIs'!$A:$A,">="&$A10,'Sales Daily KPIs'!$A:$A,"<="&$B10)) -> 0 | M10: =IF(A10="","",Settings!$B$5) -> 2
A11: 46408 | B11: =IF(A11="","",A11+6) -> 46414 | C11: Usama Rehman | D11: =IF(A11="","",COUNTIFS('Sales Daily KPIs'!$B:$B,$C11,'Sales Daily KPIs'!$A:$A,">="&$A11,'Sales Daily KPIs'!$A:$A,"<="&$B11,'Sales Daily KPIs'!$C:$C,"<>")) -> 0 | E11: =IF(A11="","",SUMIFS('Sales Daily KPIs'!$C:$C,'Sales Daily KPIs'!$B:$B,$C11,'Sales Daily KPIs'!$A:$A,">="&$A11,'Sales Daily KPIs'!$A:$A,"<="&$B11)) -> 0 | F11: =IF(A11="","",Settings!$B$2*Settings!$B$6) -> 600 | G11: =IF(A11="","",SUMIFS('Sales Daily KPIs'!$D:$D,'Sales Daily KPIs'!$B:$B,$C11,'Sales Daily KPIs'!$A:$A,">="&$A11,'Sales Daily KPIs'!$A:$A,"<="&$B11)) -> 0 | H11: =IF(A11="","",Settings!$B$3*Settings!$B$6) -> 24 | I11: =IF(A11="","",SUMIFS('Sales Daily KPIs'!$E:$E,'Sales Daily KPIs'!$B:$B,$C11,'Sales Daily KPIs'!$A:$A,">="&$A11,'Sales Daily KPIs'!$A:$A,"<="&$B11)) -> 0 | J11: =IF(A11="","",Settings!$B$4*Settings!$B$6) -> 12 | K11: =IF(A11="","",IFERROR(SUMIFS('Sales Daily KPIs'!$G:$G,'Sales Daily KPIs'!$B:$B,$C11,'Sales Daily KPIs'!$A:$A,">="&$A11,'Sales Daily KPIs'!$A:$A,"<="&$B11)/SUMIFS('Sales Daily KPIs'!$F:$F,'Sales Daily KPIs'!$B:$B,$C11,'Sales Daily KPIs'!$A:$A,">="&$A11,'Sales Daily KPIs'!$A:$A,"<="&$B11),"")) | L11: =IF(A11="","",SUMIFS('Sales Daily KPIs'!$I:$I,'Sales Daily KPIs'!$B:$B,$C11,'Sales Daily KPIs'!$A:$A,">="&$A11,'Sales Daily KPIs'!$A:$A,"<="&$B11)) -> 0 | M11: =IF(A11="","",Settings!$B$5) -> 2
A12: 46415 | B12: =IF(A12="","",A12+6) -> 46421 | C12: Usama Rehman | D12: =IF(A12="","",COUNTIFS('Sales Daily KPIs'!$B:$B,$C12,'Sales Daily KPIs'!$A:$A,">="&$A12,'Sales Daily KPIs'!$A:$A,"<="&$B12,'Sales Daily KPIs'!$C:$C,"<>")) -> 0 | E12: =IF(A12="","",SUMIFS('Sales Daily KPIs'!$C:$C,'Sales Daily KPIs'!$B:$B,$C12,'Sales Daily KPIs'!$A:$A,">="&$A12,'Sales Daily KPIs'!$A:$A,"<="&$B12)) -> 0 | F12: =IF(A12="","",Settings!$B$2*Settings!$B$6) -> 600 | G12: =IF(A12="","",SUMIFS('Sales Daily KPIs'!$D:$D,'Sales Daily KPIs'!$B:$B,$C12,'Sales Daily KPIs'!$A:$A,">="&$A12,'Sales Daily KPIs'!$A:$A,"<="&$B12)) -> 0 | H12: =IF(A12="","",Settings!$B$3*Settings!$B$6) -> 24 | I12: =IF(A12="","",SUMIFS('Sales Daily KPIs'!$E:$E,'Sales Daily KPIs'!$B:$B,$C12,'Sales Daily KPIs'!$A:$A,">="&$A12,'Sales Daily KPIs'!$A:$A,"<="&$B12)) -> 0 | J12: =IF(A12="","",Settings!$B$4*Settings!$B$6) -> 12 | K12: =IF(A12="","",IFERROR(SUMIFS('Sales Daily KPIs'!$G:$G,'Sales Daily KPIs'!$B:$B,$C12,'Sales Daily KPIs'!$A:$A,">="&$A12,'Sales Daily KPIs'!$A:$A,"<="&$B12)/SUMIFS('Sales Daily KPIs'!$F:$F,'Sales Daily KPIs'!$B:$B,$C12,'Sales Daily KPIs'!$A:$A,">="&$A12,'Sales Daily KPIs'!$A:$A,"<="&$B12),"")) | L12: =IF(A12="","",SUMIFS('Sales Daily KPIs'!$I:$I,'Sales Daily KPIs'!$B:$B,$C12,'Sales Daily KPIs'!$A:$A,">="&$A12,'Sales Daily KPIs'!$A:$A,"<="&$B12)) -> 0 | M12: =IF(A12="","",Settings!$B$5) -> 2
A13: 46422 | B13: =IF(A13="","",A13+6) -> 46428 | C13: Usama Rehman | D13: =IF(A13="","",COUNTIFS('Sales Daily KPIs'!$B:$B,$C13,'Sales Daily KPIs'!$A:$A,">="&$A13,'Sales Daily KPIs'!$A:$A,"<="&$B13,'Sales Daily KPIs'!$C:$C,"<>")) -> 0 | E13: =IF(A13="","",SUMIFS('Sales Daily KPIs'!$C:$C,'Sales Daily KPIs'!$B:$B,$C13,'Sales Daily KPIs'!$A:$A,">="&$A13,'Sales Daily KPIs'!$A:$A,"<="&$B13)) -> 0 | F13: =IF(A13="","",Settings!$B$2*Settings!$B$6) -> 600 | G13: =IF(A13="","",SUMIFS('Sales Daily KPIs'!$D:$D,'Sales Daily KPIs'!$B:$B,$C13,'Sales Daily KPIs'!$A:$A,">="&$A13,'Sales Daily KPIs'!$A:$A,"<="&$B13)) -> 0 | H13: =IF(A13="","",Settings!$B$3*Settings!$B$6) -> 24 | I13: =IF(A13="","",SUMIFS('Sales Daily KPIs'!$E:$E,'Sales Daily KPIs'!$B:$B,$C13,'Sales Daily KPIs'!$A:$A,">="&$A13,'Sales Daily KPIs'!$A:$A,"<="&$B13)) -> 0 | J13: =IF(A13="","",Settings!$B$4*Settings!$B$6) -> 12 | K13: =IF(A13="","",IFERROR(SUMIFS('Sales Daily KPIs'!$G:$G,'Sales Daily KPIs'!$B:$B,$C13,'Sales Daily KPIs'!$A:$A,">="&$A13,'Sales Daily KPIs'!$A:$A,"<="&$B13)/SUMIFS('Sales Daily KPIs'!$F:$F,'Sales Daily KPIs'!$B:$B,$C13,'Sales Daily KPIs'!$A:$A,">="&$A13,'Sales Daily KPIs'!$A:$A,"<="&$B13),"")) | L13: =IF(A13="","",SUMIFS('Sales Daily KPIs'!$I:$I,'Sales Daily KPIs'!$B:$B,$C13,'Sales Daily KPIs'!$A:$A,">="&$A13,'Sales Daily KPIs'!$A:$A,"<="&$B13)) -> 0 | M13: =IF(A13="","",Settings!$B$5) -> 2
B14: =IF(A14="","",A14+6) | D14: =IF(A14="","",COUNTIFS('Sales Daily KPIs'!$B:$B,$C14,'Sales Daily KPIs'!$A:$A,">="&$A14,'Sales Daily KPIs'!$A:$A,"<="&$B14,'Sales Daily KPIs'!$C:$C,"<>")) | E14: =IF(A14="","",SUMIFS('Sales Daily KPIs'!$C:$C,'Sales Daily KPIs'!$B:$B,$C14,'Sales Daily KPIs'!$A:$A,">="&$A14,'Sales Daily KPIs'!$A:$A,"<="&$B14)) | F14: =IF(A14="","",Settings!$B$2*Settings!$B$6) | G14: =IF(A14="","",SUMIFS('Sales Daily KPIs'!$D:$D,'Sales Daily KPIs'!$B:$B,$C14,'Sales Daily KPIs'!$A:$A,">="&$A14,'Sales Daily KPIs'!$A:$A,"<="&$B14)) | H14: =IF(A14="","",Settings!$B$3*Settings!$B$6) | I14: =IF(A14="","",SUMIFS('Sales Daily KPIs'!$E:$E,'Sales Daily KPIs'!$B:$B,$C14,'Sales Daily KPIs'!$A:$A,">="&$A14,'Sales Daily KPIs'!$A:$A,"<="&$B14)) | J14: =IF(A14="","",Settings!$B$4*Settings!$B$6) | K14: =IF(A14="","",IFERROR(SUMIFS('Sales Daily KPIs'!$G:$G,'Sales Daily KPIs'!$B:$B,$C14,'Sales Daily KPIs'!$A:$A,">="&$A14,'Sales Daily KPIs'!$A:$A,"<="&$B14)/SUMIFS('Sales Daily KPIs'!$F:$F,'Sales Daily KPIs'!$B:$B,$C14,'Sales Daily KPIs'!$A:$A,">="&$A14,'Sales Daily KPIs'!$A:$A,"<="&$B14),"")) | L14: =IF(A14="","",SUMIFS('Sales Daily KPIs'!$I:$I,'Sales Daily KPIs'!$B:$B,$C14,'Sales Daily KPIs'!$A:$A,">="&$A14,'Sales Daily KPIs'!$A:$A,"<="&$B14)) | M14: =IF(A14="","",Settings!$B$5)
B15: =IF(A15="","",A15+6) | D15: =IF(A15="","",COUNTIFS('Sales Daily KPIs'!$B:$B,$C15,'Sales Daily KPIs'!$A:$A,">="&$A15,'Sales Daily KPIs'!$A:$A,"<="&$B15,'Sales Daily KPIs'!$C:$C,"<>")) | E15: =IF(A15="","",SUMIFS('Sales Daily KPIs'!$C:$C,'Sales Daily KPIs'!$B:$B,$C15,'Sales Daily KPIs'!$A:$A,">="&$A15,'Sales Daily KPIs'!$A:$A,"<="&$B15)) | F15: =IF(A15="","",Settings!$B$2*Settings!$B$6) | G15: =IF(A15="","",SUMIFS('Sales Daily KPIs'!$D:$D,'Sales Daily KPIs'!$B:$B,$C15,'Sales Daily KPIs'!$A:$A,">="&$A15,'Sales Daily KPIs'!$A:$A,"<="&$B15)) | H15: =IF(A15="","",Settings!$B$3*Settings!$B$6) | I15: =IF(A15="","",SUMIFS('Sales Daily KPIs'!$E:$E,'Sales Daily KPIs'!$B:$B,$C15,'Sales Daily KPIs'!$A:$A,">="&$A15,'Sales Daily KPIs'!$A:$A,"<="&$B15)) | J15: =IF(A15="","",Settings!$B$4*Settings!$B$6) | K15: =IF(A15="","",IFERROR(SUMIFS('Sales Daily KPIs'!$G:$G,'Sales Daily KPIs'!$B:$B,$C15,'Sales Daily KPIs'!$A:$A,">="&$A15,'Sales Daily KPIs'!$A:$A,"<="&$B15)/SUMIFS('Sales Daily KPIs'!$F:$F,'Sales Daily KPIs'!$B:$B,$C15,'Sales Daily KPIs'!$A:$A,">="&$A15,'Sales Daily KPIs'!$A:$A,"<="&$B15),"")) | L15: =IF(A15="","",SUMIFS('Sales Daily KPIs'!$I:$I,'Sales Daily KPIs'!$B:$B,$C15,'Sales Daily KPIs'!$A:$A,">="&$A15,'Sales Daily KPIs'!$A:$A,"<="&$B15)) | M15: =IF(A15="","",Settings!$B$5)
B16: =IF(A16="","",A16+6) | D16: =IF(A16="","",COUNTIFS('Sales Daily KPIs'!$B:$B,$C16,'Sales Daily KPIs'!$A:$A,">="&$A16,'Sales Daily KPIs'!$A:$A,"<="&$B16,'Sales Daily KPIs'!$C:$C,"<>")) | E16: =IF(A16="","",SUMIFS('Sales Daily KPIs'!$C:$C,'Sales Daily KPIs'!$B:$B,$C16,'Sales Daily KPIs'!$A:$A,">="&$A16,'Sales Daily KPIs'!$A:$A,"<="&$B16)) | F16: =IF(A16="","",Settings!$B$2*Settings!$B$6) | G16: =IF(A16="","",SUMIFS('Sales Daily KPIs'!$D:$D,'Sales Daily KPIs'!$B:$B,$C16,'Sales Daily KPIs'!$A:$A,">="&$A16,'Sales Daily KPIs'!$A:$A,"<="&$B16)) | H16: =IF(A16="","",Settings!$B$3*Settings!$B$6) | I16: =IF(A16="","",SUMIFS('Sales Daily KPIs'!$E:$E,'Sales Daily KPIs'!$B:$B,$C16,'Sales Daily KPIs'!$A:$A,">="&$A16,'Sales Daily KPIs'!$A:$A,"<="&$B16)) | J16: =IF(A16="","",Settings!$B$4*Settings!$B$6) | K16: =IF(A16="","",IFERROR(SUMIFS('Sales Daily KPIs'!$G:$G,'Sales Daily KPIs'!$B:$B,$C16,'Sales Daily KPIs'!$A:$A,">="&$A16,'Sales Daily KPIs'!$A:$A,"<="&$B16)/SUMIFS('Sales Daily KPIs'!$F:$F,'Sales Daily KPIs'!$B:$B,$C16,'Sales Daily KPIs'!$A:$A,">="&$A16,'Sales Daily KPIs'!$A:$A,"<="&$B16),"")) | L16: =IF(A16="","",SUMIFS('Sales Daily KPIs'!$I:$I,'Sales Daily KPIs'!$B:$B,$C16,'Sales Daily KPIs'!$A:$A,">="&$A16,'Sales Daily KPIs'!$A:$A,"<="&$B16)) | M16: =IF(A16="","",Settings!$B$5)
B17: =IF(A17="","",A17+6) | D17: =IF(A17="","",COUNTIFS('Sales Daily KPIs'!$B:$B,$C17,'Sales Daily KPIs'!$A:$A,">="&$A17,'Sales Daily KPIs'!$A:$A,"<="&$B17,'Sales Daily KPIs'!$C:$C,"<>")) | E17: =IF(A17="","",SUMIFS('Sales Daily KPIs'!$C:$C,'Sales Daily KPIs'!$B:$B,$C17,'Sales Daily KPIs'!$A:$A,">="&$A17,'Sales Daily KPIs'!$A:$A,"<="&$B17)) | F17: =IF(A17="","",Settings!$B$2*Settings!$B$6) | G17: =IF(A17="","",SUMIFS('Sales Daily KPIs'!$D:$D,'Sales Daily KPIs'!$B:$B,$C17,'Sales Daily KPIs'!$A:$A,">="&$A17,'Sales Daily KPIs'!$A:$A,"<="&$B17)) | H17: =IF(A17="","",Settings!$B$3*Settings!$B$6) | I17: =IF(A17="","",SUMIFS('Sales Daily KPIs'!$E:$E,'Sales Daily KPIs'!$B:$B,$C17,'Sales Daily KPIs'!$A:$A,">="&$A17,'Sales Daily KPIs'!$A:$A,"<="&$B17)) | J17: =IF(A17="","",Settings!$B$4*Settings!$B$6) | K17: =IF(A17="","",IFERROR(SUMIFS('Sales Daily KPIs'!$G:$G,'Sales Daily KPIs'!$B:$B,$C17,'Sales Daily KPIs'!$A:$A,">="&$A17,'Sales Daily KPIs'!$A:$A,"<="&$B17)/SUMIFS('Sales Daily KPIs'!$F:$F,'Sales Daily KPIs'!$B:$B,$C17,'Sales Daily KPIs'!$A:$A,">="&$A17,'Sales Daily KPIs'!$A:$A,"<="&$B17),"")) | L17: =IF(A17="","",SUMIFS('Sales Daily KPIs'!$I:$I,'Sales Daily KPIs'!$B:$B,$C17,'Sales Daily KPIs'!$A:$A,">="&$A17,'Sales Daily KPIs'!$A:$A,"<="&$B17)) | M17: =IF(A17="","",Settings!$B$5)
B18: =IF(A18="","",A18+6) | D18: =IF(A18="","",COUNTIFS('Sales Daily KPIs'!$B:$B,$C18,'Sales Daily KPIs'!$A:$A,">="&$A18,'Sales Daily KPIs'!$A:$A,"<="&$B18,'Sales Daily KPIs'!$C:$C,"<>")) | E18: =IF(A18="","",SUMIFS('Sales Daily KPIs'!$C:$C,'Sales Daily KPIs'!$B:$B,$C18,'Sales Daily KPIs'!$A:$A,">="&$A18,'Sales Daily KPIs'!$A:$A,"<="&$B18)) | F18: =IF(A18="","",Settings!$B$2*Settings!$B$6) | G18: =IF(A18="","",SUMIFS('Sales Daily KPIs'!$D:$D,'Sales Daily KPIs'!$B:$B,$C18,'Sales Daily KPIs'!$A:$A,">="&$A18,'Sales Daily KPIs'!$A:$A,"<="&$B18)) | H18: =IF(A18="","",Settings!$B$3*Settings!$B$6) | I18: =IF(A18="","",SUMIFS('Sales Daily KPIs'!$E:$E,'Sales Daily KPIs'!$B:$B,$C18,'Sales Daily KPIs'!$A:$A,">="&$A18,'Sales Daily KPIs'!$A:$A,"<="&$B18)) | J18: =IF(A18="","",Settings!$B$4*Settings!$B$6) | K18: =IF(A18="","",IFERROR(SUMIFS('Sales Daily KPIs'!$G:$G,'Sales Daily KPIs'!$B:$B,$C18,'Sales Daily KPIs'!$A:$A,">="&$A18,'Sales Daily KPIs'!$A:$A,"<="&$B18)/SUMIFS('Sales Daily KPIs'!$F:$F,'Sales Daily KPIs'!$B:$B,$C18,'Sales Daily KPIs'!$A:$A,">="&$A18,'Sales Daily KPIs'!$A:$A,"<="&$B18),"")) | L18: =IF(A18="","",SUMIFS('Sales Daily KPIs'!$I:$I,'Sales Daily KPIs'!$B:$B,$C18,'Sales Daily KPIs'!$A:$A,">="&$A18,'Sales Daily KPIs'!$A:$A,"<="&$B18)) | M18: =IF(A18="","",Settings!$B$5)
B19: =IF(A19="","",A19+6) | D19: =IF(A19="","",COUNTIFS('Sales Daily KPIs'!$B:$B,$C19,'Sales Daily KPIs'!$A:$A,">="&$A19,'Sales Daily KPIs'!$A:$A,"<="&$B19,'Sales Daily KPIs'!$C:$C,"<>")) | E19: =IF(A19="","",SUMIFS('Sales Daily KPIs'!$C:$C,'Sales Daily KPIs'!$B:$B,$C19,'Sales Daily KPIs'!$A:$A,">="&$A19,'Sales Daily KPIs'!$A:$A,"<="&$B19)) | F19: =IF(A19="","",Settings!$B$2*Settings!$B$6) | G19: =IF(A19="","",SUMIFS('Sales Daily KPIs'!$D:$D,'Sales Daily KPIs'!$B:$B,$C19,'Sales Daily KPIs'!$A:$A,">="&$A19,'Sales Daily KPIs'!$A:$A,"<="&$B19)) | H19: =IF(A19="","",Settings!$B$3*Settings!$B$6) | I19: =IF(A19="","",SUMIFS('Sales Daily KPIs'!$E:$E,'Sales Daily KPIs'!$B:$B,$C19,'Sales Daily KPIs'!$A:$A,">="&$A19,'Sales Daily KPIs'!$A:$A,"<="&$B19)) | J19: =IF(A19="","",Settings!$B$4*Settings!$B$6) | K19: =IF(A19="","",IFERROR(SUMIFS('Sales Daily KPIs'!$G:$G,'Sales Daily KPIs'!$B:$B,$C19,'Sales Daily KPIs'!$A:$A,">="&$A19,'Sales Daily KPIs'!$A:$A,"<="&$B19)/SUMIFS('Sales Daily KPIs'!$F:$F,'Sales Daily KPIs'!$B:$B,$C19,'Sales Daily KPIs'!$A:$A,">="&$A19,'Sales Daily KPIs'!$A:$A,"<="&$B19),"")) | L19: =IF(A19="","",SUMIFS('Sales Daily KPIs'!$I:$I,'Sales Daily KPIs'!$B:$B,$C19,'Sales Daily KPIs'!$A:$A,">="&$A19,'Sales Daily KPIs'!$A:$A,"<="&$B19)) | M19: =IF(A19="","",Settings!$B$5)
B20: =IF(A20="","",A20+6) | D20: =IF(A20="","",COUNTIFS('Sales Daily KPIs'!$B:$B,$C20,'Sales Daily KPIs'!$A:$A,">="&$A20,'Sales Daily KPIs'!$A:$A,"<="&$B20,'Sales Daily KPIs'!$C:$C,"<>")) | E20: =IF(A20="","",SUMIFS('Sales Daily KPIs'!$C:$C,'Sales Daily KPIs'!$B:$B,$C20,'Sales Daily KPIs'!$A:$A,">="&$A20,'Sales Daily KPIs'!$A:$A,"<="&$B20)) | F20: =IF(A20="","",Settings!$B$2*Settings!$B$6) | G20: =IF(A20="","",SUMIFS('Sales Daily KPIs'!$D:$D,'Sales Daily KPIs'!$B:$B,$C20,'Sales Daily KPIs'!$A:$A,">="&$A20,'Sales Daily KPIs'!$A:$A,"<="&$B20)) | H20: =IF(A20="","",Settings!$B$3*Settings!$B$6) | I20: =IF(A20="","",SUMIFS('Sales Daily KPIs'!$E:$E,'Sales Daily KPIs'!$B:$B,$C20,'Sales Daily KPIs'!$A:$A,">="&$A20,'Sales Daily KPIs'!$A:$A,"<="&$B20)) | J20: =IF(A20="","",Settings!$B$4*Settings!$B$6) | K20: =IF(A20="","",IFERROR(SUMIFS('Sales Daily KPIs'!$G:$G,'Sales Daily KPIs'!$B:$B,$C20,'Sales Daily KPIs'!$A:$A,">="&$A20,'Sales Daily KPIs'!$A:$A,"<="&$B20)/SUMIFS('Sales Daily KPIs'!$F:$F,'Sales Daily KPIs'!$B:$B,$C20,'Sales Daily KPIs'!$A:$A,">="&$A20,'Sales Daily KPIs'!$A:$A,"<="&$B20),"")) | L20: =IF(A20="","",SUMIFS('Sales Daily KPIs'!$I:$I,'Sales Daily KPIs'!$B:$B,$C20,'Sales Daily KPIs'!$A:$A,">="&$A20,'Sales Daily KPIs'!$A:$A,"<="&$B20)) | M20: =IF(A20="","",Settings!$B$5)
B21: =IF(A21="","",A21+6) | D21: =IF(A21="","",COUNTIFS('Sales Daily KPIs'!$B:$B,$C21,'Sales Daily KPIs'!$A:$A,">="&$A21,'Sales Daily KPIs'!$A:$A,"<="&$B21,'Sales Daily KPIs'!$C:$C,"<>")) | E21: =IF(A21="","",SUMIFS('Sales Daily KPIs'!$C:$C,'Sales Daily KPIs'!$B:$B,$C21,'Sales Daily KPIs'!$A:$A,">="&$A21,'Sales Daily KPIs'!$A:$A,"<="&$B21)) | F21: =IF(A21="","",Settings!$B$2*Settings!$B$6) | G21: =IF(A21="","",SUMIFS('Sales Daily KPIs'!$D:$D,'Sales Daily KPIs'!$B:$B,$C21,'Sales Daily KPIs'!$A:$A,">="&$A21,'Sales Daily KPIs'!$A:$A,"<="&$B21)) | H21: =IF(A21="","",Settings!$B$3*Settings!$B$6) | I21: =IF(A21="","",SUMIFS('Sales Daily KPIs'!$E:$E,'Sales Daily KPIs'!$B:$B,$C21,'Sales Daily KPIs'!$A:$A,">="&$A21,'Sales Daily KPIs'!$A:$A,"<="&$B21)) | J21: =IF(A21="","",Settings!$B$4*Settings!$B$6) | K21: =IF(A21="","",IFERROR(SUMIFS('Sales Daily KPIs'!$G:$G,'Sales Daily KPIs'!$B:$B,$C21,'Sales Daily KPIs'!$A:$A,">="&$A21,'Sales Daily KPIs'!$A:$A,"<="&$B21)/SUMIFS('Sales Daily KPIs'!$F:$F,'Sales Daily KPIs'!$B:$B,$C21,'Sales Daily KPIs'!$A:$A,">="&$A21,'Sales Daily KPIs'!$A:$A,"<="&$B21),"")) | L21: =IF(A21="","",SUMIFS('Sales Daily KPIs'!$I:$I,'Sales Daily KPIs'!$B:$B,$C21,'Sales Daily KPIs'!$A:$A,">="&$A21,'Sales Daily KPIs'!$A:$A,"<="&$B21)) | M21: =IF(A21="","",Settings!$B$5)
B22: =IF(A22="","",A22+6) | D22: =IF(A22="","",COUNTIFS('Sales Daily KPIs'!$B:$B,$C22,'Sales Daily KPIs'!$A:$A,">="&$A22,'Sales Daily KPIs'!$A:$A,"<="&$B22,'Sales Daily KPIs'!$C:$C,"<>")) | E22: =IF(A22="","",SUMIFS('Sales Daily KPIs'!$C:$C,'Sales Daily KPIs'!$B:$B,$C22,'Sales Daily KPIs'!$A:$A,">="&$A22,'Sales Daily KPIs'!$A:$A,"<="&$B22)) | F22: =IF(A22="","",Settings!$B$2*Settings!$B$6) | G22: =IF(A22="","",SUMIFS('Sales Daily KPIs'!$D:$D,'Sales Daily KPIs'!$B:$B,$C22,'Sales Daily KPIs'!$A:$A,">="&$A22,'Sales Daily KPIs'!$A:$A,"<="&$B22)) | H22: =IF(A22="","",Settings!$B$3*Settings!$B$6) | I22: =IF(A22="","",SUMIFS('Sales Daily KPIs'!$E:$E,'Sales Daily KPIs'!$B:$B,$C22,'Sales Daily KPIs'!$A:$A,">="&$A22,'Sales Daily KPIs'!$A:$A,"<="&$B22)) | J22: =IF(A22="","",Settings!$B$4*Settings!$B$6) | K22: =IF(A22="","",IFERROR(SUMIFS('Sales Daily KPIs'!$G:$G,'Sales Daily KPIs'!$B:$B,$C22,'Sales Daily KPIs'!$A:$A,">="&$A22,'Sales Daily KPIs'!$A:$A,"<="&$B22)/SUMIFS('Sales Daily KPIs'!$F:$F,'Sales Daily KPIs'!$B:$B,$C22,'Sales Daily KPIs'!$A:$A,">="&$A22,'Sales Daily KPIs'!$A:$A,"<="&$B22),"")) | L22: =IF(A22="","",SUMIFS('Sales Daily KPIs'!$I:$I,'Sales Daily KPIs'!$B:$B,$C22,'Sales Daily KPIs'!$A:$A,">="&$A22,'Sales Daily KPIs'!$A:$A,"<="&$B22)) | M22: =IF(A22="","",Settings!$B$5)
B23: =IF(A23="","",A23+6) | D23: =IF(A23="","",COUNTIFS('Sales Daily KPIs'!$B:$B,$C23,'Sales Daily KPIs'!$A:$A,">="&$A23,'Sales Daily KPIs'!$A:$A,"<="&$B23,'Sales Daily KPIs'!$C:$C,"<>")) | E23: =IF(A23="","",SUMIFS('Sales Daily KPIs'!$C:$C,'Sales Daily KPIs'!$B:$B,$C23,'Sales Daily KPIs'!$A:$A,">="&$A23,'Sales Daily KPIs'!$A:$A,"<="&$B23)) | F23: =IF(A23="","",Settings!$B$2*Settings!$B$6) | G23: =IF(A23="","",SUMIFS('Sales Daily KPIs'!$D:$D,'Sales Daily KPIs'!$B:$B,$C23,'Sales Daily KPIs'!$A:$A,">="&$A23,'Sales Daily KPIs'!$A:$A,"<="&$B23)) | H23: =IF(A23="","",Settings!$B$3*Settings!$B$6) | I23: =IF(A23="","",SUMIFS('Sales Daily KPIs'!$E:$E,'Sales Daily KPIs'!$B:$B,$C23,'Sales Daily KPIs'!$A:$A,">="&$A23,'Sales Daily KPIs'!$A:$A,"<="&$B23)) | J23: =IF(A23="","",Settings!$B$4*Settings!$B$6) | K23: =IF(A23="","",IFERROR(SUMIFS('Sales Daily KPIs'!$G:$G,'Sales Daily KPIs'!$B:$B,$C23,'Sales Daily KPIs'!$A:$A,">="&$A23,'Sales Daily KPIs'!$A:$A,"<="&$B23)/SUMIFS('Sales Daily KPIs'!$F:$F,'Sales Daily KPIs'!$B:$B,$C23,'Sales Daily KPIs'!$A:$A,">="&$A23,'Sales Daily KPIs'!$A:$A,"<="&$B23),"")) | L23: =IF(A23="","",SUMIFS('Sales Daily KPIs'!$I:$I,'Sales Daily KPIs'!$B:$B,$C23,'Sales Daily KPIs'!$A:$A,">="&$A23,'Sales Daily KPIs'!$A:$A,"<="&$B23)) | M23: =IF(A23="","",Settings!$B$5)
B24: =IF(A24="","",A24+6) | D24: =IF(A24="","",COUNTIFS('Sales Daily KPIs'!$B:$B,$C24,'Sales Daily KPIs'!$A:$A,">="&$A24,'Sales Daily KPIs'!$A:$A,"<="&$B24,'Sales Daily KPIs'!$C:$C,"<>")) | E24: =IF(A24="","",SUMIFS('Sales Daily KPIs'!$C:$C,'Sales Daily KPIs'!$B:$B,$C24,'Sales Daily KPIs'!$A:$A,">="&$A24,'Sales Daily KPIs'!$A:$A,"<="&$B24)) | F24: =IF(A24="","",Settings!$B$2*Settings!$B$6) | G24: =IF(A24="","",SUMIFS('Sales Daily KPIs'!$D:$D,'Sales Daily KPIs'!$B:$B,$C24,'Sales Daily KPIs'!$A:$A,">="&$A24,'Sales Daily KPIs'!$A:$A,"<="&$B24)) | H24: =IF(A24="","",Settings!$B$3*Settings!$B$6) | I24: =IF(A24="","",SUMIFS('Sales Daily KPIs'!$E:$E,'Sales Daily KPIs'!$B:$B,$C24,'Sales Daily KPIs'!$A:$A,">="&$A24,'Sales Daily KPIs'!$A:$A,"<="&$B24)) | J24: =IF(A24="","",Settings!$B$4*Settings!$B$6) | K24: =IF(A24="","",IFERROR(SUMIFS('Sales Daily KPIs'!$G:$G,'Sales Daily KPIs'!$B:$B,$C24,'Sales Daily KPIs'!$A:$A,">="&$A24,'Sales Daily KPIs'!$A:$A,"<="&$B24)/SUMIFS('Sales Daily KPIs'!$F:$F,'Sales Daily KPIs'!$B:$B,$C24,'Sales Daily KPIs'!$A:$A,">="&$A24,'Sales Daily KPIs'!$A:$A,"<="&$B24),"")) | L24: =IF(A24="","",SUMIFS('Sales Daily KPIs'!$I:$I,'Sales Daily KPIs'!$B:$B,$C24,'Sales Daily KPIs'!$A:$A,">="&$A24,'Sales Daily KPIs'!$A:$A,"<="&$B24)) | M24: =IF(A24="","",Settings!$B$5)
B25: =IF(A25="","",A25+6) | D25: =IF(A25="","",COUNTIFS('Sales Daily KPIs'!$B:$B,$C25,'Sales Daily KPIs'!$A:$A,">="&$A25,'Sales Daily KPIs'!$A:$A,"<="&$B25,'Sales Daily KPIs'!$C:$C,"<>")) | E25: =IF(A25="","",SUMIFS('Sales Daily KPIs'!$C:$C,'Sales Daily KPIs'!$B:$B,$C25,'Sales Daily KPIs'!$A:$A,">="&$A25,'Sales Daily KPIs'!$A:$A,"<="&$B25)) | F25: =IF(A25="","",Settings!$B$2*Settings!$B$6) | G25: =IF(A25="","",SUMIFS('Sales Daily KPIs'!$D:$D,'Sales Daily KPIs'!$B:$B,$C25,'Sales Daily KPIs'!$A:$A,">="&$A25,'Sales Daily KPIs'!$A:$A,"<="&$B25)) | H25: =IF(A25="","",Settings!$B$3*Settings!$B$6) | I25: =IF(A25="","",SUMIFS('Sales Daily KPIs'!$E:$E,'Sales Daily KPIs'!$B:$B,$C25,'Sales Daily KPIs'!$A:$A,">="&$A25,'Sales Daily KPIs'!$A:$A,"<="&$B25)) | J25: =IF(A25="","",Settings!$B$4*Settings!$B$6) | K25: =IF(A25="","",IFERROR(SUMIFS('Sales Daily KPIs'!$G:$G,'Sales Daily KPIs'!$B:$B,$C25,'Sales Daily KPIs'!$A:$A,">="&$A25,'Sales Daily KPIs'!$A:$A,"<="&$B25)/SUMIFS('Sales Daily KPIs'!$F:$F,'Sales Daily KPIs'!$B:$B,$C25,'Sales Daily KPIs'!$A:$A,">="&$A25,'Sales Daily KPIs'!$A:$A,"<="&$B25),"")) | L25: =IF(A25="","",SUMIFS('Sales Daily KPIs'!$I:$I,'Sales Daily KPIs'!$B:$B,$C25,'Sales Daily KPIs'!$A:$A,">="&$A25,'Sales Daily KPIs'!$A:$A,"<="&$B25)) | M25: =IF(A25="","",Settings!$B$5)
... B121: =IF(A121="","",A121+6) | D121: =IF(A121="","",COUNTIFS('Sales Daily KPIs'!$B:$B,$C121,'Sales Daily KPIs'!$A:$A,">="&$A121,'Sales Daily KPIs'!$A:$A,"<="&$B121,'Sales Daily KPIs'!$C:$C,"<>")) | E121: =IF(A121="","",SUMIFS('Sales Daily KPIs'!$C:$C,'Sales Daily KPIs'!$B:$B,$C121,'Sales Daily KPIs'!$A:$A,">="&$A121,'Sales Daily KPIs'!$A:$A,"<="&$B121)) | F121: =IF(A121="","",Settings!$B$2*Settings!$B$6) | G121: =IF(A121="","",SUMIFS('Sales Daily KPIs'!$D:$D,'Sales Daily KPIs'!$B:$B,$C121,'Sales Daily KPIs'!$A:$A,">="&$A121,'Sales Daily KPIs'!$A:$A,"<="&$B121)) | H121: =IF(A121="","",Settings!$B$3*Settings!$B$6) | I121: =IF(A121="","",SUMIFS('Sales Daily KPIs'!$E:$E,'Sales Daily KPIs'!$B:$B,$C121,'Sales Daily KPIs'!$A:$A,">="&$A121,'Sales Daily KPIs'!$A:$A,"<="&$B121)) | J121: =IF(A121="","",Settings!$B$4*Settings!$B$6) | K121: =IF(A121="","",IFERROR(SUMIFS('Sales Daily KPIs'!$G:$G,'Sales Daily KPIs'!$B:$B,$C121,'Sales Daily KPIs'!$A:$A,">="&$A121,'Sales Daily KPIs'!$A:$A,"<="&$B121)/SUMIFS('Sales Daily KPIs'!$F:$F,'Sales Daily KPIs'!$B:$B,$C121,'Sales Daily KPIs'!$A:$A,">="&$A121,'Sales Daily KPIs'!$A:$A,"<="&$B121),"")) | L121: =IF(A121="","",SUMIFS('Sales Daily KPIs'!$I:$I,'Sales Daily KPIs'!$B:$B,$C121,'Sales Daily KPIs'!$A:$A,">="&$A121,'Sales Daily KPIs'!$A:$A,"<="&$B121)) | M121: =IF(A121="","",Settings!$B$5)

Sheet Spending
A1: Date | B1: Category | C1: Description | D1: Paid to | E1: Amount excl. VAT (AED) | F1: VAT charged? (Y/N) | G1: VAT (AED) | H1: Total paid (AED) | I1: Payment method | J1: Recurring | K1: Receipt link | L1: Notes
A2: 46344 | B2: Software and subscriptions | C2: EXAMPLE: editing software, monthly | D2: Software vendor | E2: 200 | F2: Y | G2: =IF(E2="","",IF(F2="Y",E2*Settings!$B$16,0)) -> 10 | H2: =IF(E2="","",E2+G2) -> 210 | I2: Card | J2: Monthly | L2: Delete this row
G3: =IF(E3="","",IF(F3="Y",E3*Settings!$B$16,0)) | H3: =IF(E3="","",E3+G3)
G4: =IF(E4="","",IF(F4="Y",E4*Settings!$B$16,0)) | H4: =IF(E4="","",E4+G4)
G5: =IF(E5="","",IF(F5="Y",E5*Settings!$B$16,0)) | H5: =IF(E5="","",E5+G5)
G6: =IF(E6="","",IF(F6="Y",E6*Settings!$B$16,0)) | H6: =IF(E6="","",E6+G6)
G7: =IF(E7="","",IF(F7="Y",E7*Settings!$B$16,0)) | H7: =IF(E7="","",E7+G7)
G8: =IF(E8="","",IF(F8="Y",E8*Settings!$B$16,0)) | H8: =IF(E8="","",E8+G8)
G9: =IF(E9="","",IF(F9="Y",E9*Settings!$B$16,0)) | H9: =IF(E9="","",E9+G9)
G10: =IF(E10="","",IF(F10="Y",E10*Settings!$B$16,0)) | H10: =IF(E10="","",E10+G10)
G11: =IF(E11="","",IF(F11="Y",E11*Settings!$B$16,0)) | H11: =IF(E11="","",E11+G11)
G12: =IF(E12="","",IF(F12="Y",E12*Settings!$B$16,0)) | H12: =IF(E12="","",E12+G12)
G13: =IF(E13="","",IF(F13="Y",E13*Settings!$B$16,0)) | H13: =IF(E13="","",E13+G13)
G14: =IF(E14="","",IF(F14="Y",E14*Settings!$B$16,0)) | H14: =IF(E14="","",E14+G14)
... G1001: =IF(E1001="","",IF(F1001="Y",E1001*Settings!$B$16,0)) | H1001: =IF(E1001="","",E1001+G1001)

Sheet Earnings
A1: Invoice no. | B1: Invoice date | C1: Client | D1: Service | E1: Description | F1: Amount excl. VAT (AED) | G1: VAT charged? (Y/N) | H1: VAT (AED) | I1: Invoice total (AED) | J1: Due date | K1: Paid on | L1: Amount received (AED) | M1: Status | N1: Days overdue | O1: Notes
A2: YON-2026-000 | B2: 46344 | C2: EXAMPLE Spa Co | D2: Growth | E2: EXAMPLE: November content package | F2: 7500 | G2: N | H2: =IF(F2="","",IF(G2="Y",F2*Settings!$B$16,0)) -> 0 | I2: =IF(F2="","",F2+H2) -> 7500 | J2: =IF(B2="","",B2+Settings!$B$17) -> 46349 | K2: 46344 | L2: 7500 | M2: =IF(F2="","",IF(AND(L2<>"",L2>=I2),"Paid",IF(AND(L2<>"",L2>0),"Part paid",IF(TODAY()>J2,"Overdue","Due")))) -> Paid | N2: =IF(M2="Overdue",TODAY()-J2,"") | O2: Delete this row
H3: =IF(F3="","",IF(G3="Y",F3*Settings!$B$16,0)) | I3: =IF(F3="","",F3+H3) | J3: =IF(B3="","",B3+Settings!$B$17) | M3: =IF(F3="","",IF(AND(L3<>"",L3>=I3),"Paid",IF(AND(L3<>"",L3>0),"Part paid",IF(TODAY()>J3,"Overdue","Due")))) | N3: =IF(M3="Overdue",TODAY()-J3,"")
H4: =IF(F4="","",IF(G4="Y",F4*Settings!$B$16,0)) | I4: =IF(F4="","",F4+H4) | J4: =IF(B4="","",B4+Settings!$B$17) | M4: =IF(F4="","",IF(AND(L4<>"",L4>=I4),"Paid",IF(AND(L4<>"",L4>0),"Part paid",IF(TODAY()>J4,"Overdue","Due")))) | N4: =IF(M4="Overdue",TODAY()-J4,"")
H5: =IF(F5="","",IF(G5="Y",F5*Settings!$B$16,0)) | I5: =IF(F5="","",F5+H5) | J5: =IF(B5="","",B5+Settings!$B$17) | M5: =IF(F5="","",IF(AND(L5<>"",L5>=I5),"Paid",IF(AND(L5<>"",L5>0),"Part paid",IF(TODAY()>J5,"Overdue","Due")))) | N5: =IF(M5="Overdue",TODAY()-J5,"")
H6: =IF(F6="","",IF(G6="Y",F6*Settings!$B$16,0)) | I6: =IF(F6="","",F6+H6) | J6: =IF(B6="","",B6+Settings!$B$17) | M6: =IF(F6="","",IF(AND(L6<>"",L6>=I6),"Paid",IF(AND(L6<>"",L6>0),"Part paid",IF(TODAY()>J6,"Overdue","Due")))) | N6: =IF(M6="Overdue",TODAY()-J6,"")
H7: =IF(F7="","",IF(G7="Y",F7*Settings!$B$16,0)) | I7: =IF(F7="","",F7+H7) | J7: =IF(B7="","",B7+Settings!$B$17) | M7: =IF(F7="","",IF(AND(L7<>"",L7>=I7),"Paid",IF(AND(L7<>"",L7>0),"Part paid",IF(TODAY()>J7,"Overdue","Due")))) | N7: =IF(M7="Overdue",TODAY()-J7,"")
H8: =IF(F8="","",IF(G8="Y",F8*Settings!$B$16,0)) | I8: =IF(F8="","",F8+H8) | J8: =IF(B8="","",B8+Settings!$B$17) | M8: =IF(F8="","",IF(AND(L8<>"",L8>=I8),"Paid",IF(AND(L8<>"",L8>0),"Part paid",IF(TODAY()>J8,"Overdue","Due")))) | N8: =IF(M8="Overdue",TODAY()-J8,"")
H9: =IF(F9="","",IF(G9="Y",F9*Settings!$B$16,0)) | I9: =IF(F9="","",F9+H9) | J9: =IF(B9="","",B9+Settings!$B$17) | M9: =IF(F9="","",IF(AND(L9<>"",L9>=I9),"Paid",IF(AND(L9<>"",L9>0),"Part paid",IF(TODAY()>J9,"Overdue","Due")))) | N9: =IF(M9="Overdue",TODAY()-J9,"")
H10: =IF(F10="","",IF(G10="Y",F10*Settings!$B$16,0)) | I10: =IF(F10="","",F10+H10) | J10: =IF(B10="","",B10+Settings!$B$17) | M10: =IF(F10="","",IF(AND(L10<>"",L10>=I10),"Paid",IF(AND(L10<>"",L10>0),"Part paid",IF(TODAY()>J10,"Overdue","Due")))) | N10: =IF(M10="Overdue",TODAY()-J10,"")
H11: =IF(F11="","",IF(G11="Y",F11*Settings!$B$16,0)) | I11: =IF(F11="","",F11+H11) | J11: =IF(B11="","",B11+Settings!$B$17) | M11: =IF(F11="","",IF(AND(L11<>"",L11>=I11),"Paid",IF(AND(L11<>"",L11>0),"Part paid",IF(TODAY()>J11,"Overdue","Due")))) | N11: =IF(M11="Overdue",TODAY()-J11,"")
H12: =IF(F12="","",IF(G12="Y",F12*Settings!$B$16,0)) | I12: =IF(F12="","",F12+H12) | J12: =IF(B12="","",B12+Settings!$B$17) | M12: =IF(F12="","",IF(AND(L12<>"",L12>=I12),"Paid",IF(AND(L12<>"",L12>0),"Part paid",IF(TODAY()>J12,"Overdue","Due")))) | N12: =IF(M12="Overdue",TODAY()-J12,"")
H13: =IF(F13="","",IF(G13="Y",F13*Settings!$B$16,0)) | I13: =IF(F13="","",F13+H13) | J13: =IF(B13="","",B13+Settings!$B$17) | M13: =IF(F13="","",IF(AND(L13<>"",L13>=I13),"Paid",IF(AND(L13<>"",L13>0),"Part paid",IF(TODAY()>J13,"Overdue","Due")))) | N13: =IF(M13="Overdue",TODAY()-J13,"")
H14: =IF(F14="","",IF(G14="Y",F14*Settings!$B$16,0)) | I14: =IF(F14="","",F14+H14) | J14: =IF(B14="","",B14+Settings!$B$17) | M14: =IF(F14="","",IF(AND(L14<>"",L14>=I14),"Paid",IF(AND(L14<>"",L14>0),"Part paid",IF(TODAY()>J14,"Overdue","Due")))) | N14: =IF(M14="Overdue",TODAY()-J14,"")
... H1001: =IF(F1001="","",IF(G1001="Y",F1001*Settings!$B$16,0)) | I1001: =IF(F1001="","",F1001+H1001) | J1001: =IF(B1001="","",B1001+Settings!$B$17) | M1001: =IF(F1001="","",IF(AND(L1001<>"",L1001>=I1001),"Paid",IF(AND(L1001<>"",L1001>0),"Part paid",IF(TODAY()>J1001,"Overdue","Due")))) | N1001: =IF(M1001="Overdue",TODAY()-J1001,"")

Sheet Monthly Summary
A1: Month | B1: Invoiced excl. VAT (AED) | C1: Cash received (AED) | D1: Spent excl. VAT (AED) | E1: Profit (AED) | F1: Margin | G1: Unpaid invoices from this month (AED) | H1: VAT collected minus VAT paid (AED)
A2: 46327 | B2: =IF(A2="","",SUMIFS(Earnings!$F:$F,Earnings!$B:$B,">="&$A2,Earnings!$B:$B,"<"&EDATE($A2,1))) -> 7500 | C2: =IF(A2="","",SUMIFS(Earnings!$L:$L,Earnings!$K:$K,">="&$A2,Earnings!$K:$K,"<"&EDATE($A2,1))) -> 7500 | D2: =IF(A2="","",SUMIFS(Spending!$E:$E,Spending!$A:$A,">="&$A2,Spending!$A:$A,"<"&EDATE($A2,1))) -> 200 | E2: =IF(A2="","",B2-D2) -> 7300 | F2: =IF(OR(A2="",B2=0),"",E2/B2) -> 0.97333333 | G2: =IF(A2="","",SUMIFS(Earnings!$I:$I,Earnings!$B:$B,">="&$A2,Earnings!$B:$B,"<"&EDATE($A2,1))-SUMIFS(Earnings!$L:$L,Earnings!$B:$B,">="&$A2,Earnings!$B:$B,"<"&EDATE($A2,1))) -> 0 | H2: =IF(A2="","",SUMIFS(Earnings!$H:$H,Earnings!$B:$B,">="&$A2,Earnings!$B:$B,"<"&EDATE($A2,1))-SUMIFS(Spending!$G:$G,Spending!$A:$A,">="&$A2,Spending!$A:$A,"<"&EDATE($A2,1))) -> -10
A3: 46357 | B3: =IF(A3="","",SUMIFS(Earnings!$F:$F,Earnings!$B:$B,">="&$A3,Earnings!$B:$B,"<"&EDATE($A3,1))) -> 0 | C3: =IF(A3="","",SUMIFS(Earnings!$L:$L,Earnings!$K:$K,">="&$A3,Earnings!$K:$K,"<"&EDATE($A3,1))) -> 0 | D3: =IF(A3="","",SUMIFS(Spending!$E:$E,Spending!$A:$A,">="&$A3,Spending!$A:$A,"<"&EDATE($A3,1))) -> 0 | E3: =IF(A3="","",B3-D3) -> 0 | F3: =IF(OR(A3="",B3=0),"",E3/B3) | G3: =IF(A3="","",SUMIFS(Earnings!$I:$I,Earnings!$B:$B,">="&$A3,Earnings!$B:$B,"<"&EDATE($A3,1))-SUMIFS(Earnings!$L:$L,Earnings!$B:$B,">="&$A3,Earnings!$B:$B,"<"&EDATE($A3,1))) -> 0 | H3: =IF(A3="","",SUMIFS(Earnings!$H:$H,Earnings!$B:$B,">="&$A3,Earnings!$B:$B,"<"&EDATE($A3,1))-SUMIFS(Spending!$G:$G,Spending!$A:$A,">="&$A3,Spending!$A:$A,"<"&EDATE($A3,1))) -> 0
A4: 46388 | B4: =IF(A4="","",SUMIFS(Earnings!$F:$F,Earnings!$B:$B,">="&$A4,Earnings!$B:$B,"<"&EDATE($A4,1))) -> 0 | C4: =IF(A4="","",SUMIFS(Earnings!$L:$L,Earnings!$K:$K,">="&$A4,Earnings!$K:$K,"<"&EDATE($A4,1))) -> 0 | D4: =IF(A4="","",SUMIFS(Spending!$E:$E,Spending!$A:$A,">="&$A4,Spending!$A:$A,"<"&EDATE($A4,1))) -> 0 | E4: =IF(A4="","",B4-D4) -> 0 | F4: =IF(OR(A4="",B4=0),"",E4/B4) | G4: =IF(A4="","",SUMIFS(Earnings!$I:$I,Earnings!$B:$B,">="&$A4,Earnings!$B:$B,"<"&EDATE($A4,1))-SUMIFS(Earnings!$L:$L,Earnings!$B:$B,">="&$A4,Earnings!$B:$B,"<"&EDATE($A4,1))) -> 0 | H4: =IF(A4="","",SUMIFS(Earnings!$H:$H,Earnings!$B:$B,">="&$A4,Earnings!$B:$B,"<"&EDATE($A4,1))-SUMIFS(Spending!$G:$G,Spending!$A:$A,">="&$A4,Spending!$A:$A,"<"&EDATE($A4,1))) -> 0
A5: 46419 | B5: =IF(A5="","",SUMIFS(Earnings!$F:$F,Earnings!$B:$B,">="&$A5,Earnings!$B:$B,"<"&EDATE($A5,1))) -> 0 | C5: =IF(A5="","",SUMIFS(Earnings!$L:$L,Earnings!$K:$K,">="&$A5,Earnings!$K:$K,"<"&EDATE($A5,1))) -> 0 | D5: =IF(A5="","",SUMIFS(Spending!$E:$E,Spending!$A:$A,">="&$A5,Spending!$A:$A,"<"&EDATE($A5,1))) -> 0 | E5: =IF(A5="","",B5-D5) -> 0 | F5: =IF(OR(A5="",B5=0),"",E5/B5) | G5: =IF(A5="","",SUMIFS(Earnings!$I:$I,Earnings!$B:$B,">="&$A5,Earnings!$B:$B,"<"&EDATE($A5,1))-SUMIFS(Earnings!$L:$L,Earnings!$B:$B,">="&$A5,Earnings!$B:$B,"<"&EDATE($A5,1))) -> 0 | H5: =IF(A5="","",SUMIFS(Earnings!$H:$H,Earnings!$B:$B,">="&$A5,Earnings!$B:$B,"<"&EDATE($A5,1))-SUMIFS(Spending!$G:$G,Spending!$A:$A,">="&$A5,Spending!$A:$A,"<"&EDATE($A5,1))) -> 0
A6: 46447 | B6: =IF(A6="","",SUMIFS(Earnings!$F:$F,Earnings!$B:$B,">="&$A6,Earnings!$B:$B,"<"&EDATE($A6,1))) -> 0 | C6: =IF(A6="","",SUMIFS(Earnings!$L:$L,Earnings!$K:$K,">="&$A6,Earnings!$K:$K,"<"&EDATE($A6,1))) -> 0 | D6: =IF(A6="","",SUMIFS(Spending!$E:$E,Spending!$A:$A,">="&$A6,Spending!$A:$A,"<"&EDATE($A6,1))) -> 0 | E6: =IF(A6="","",B6-D6) -> 0 | F6: =IF(OR(A6="",B6=0),"",E6/B6) | G6: =IF(A6="","",SUMIFS(Earnings!$I:$I,Earnings!$B:$B,">="&$A6,Earnings!$B:$B,"<"&EDATE($A6,1))-SUMIFS(Earnings!$L:$L,Earnings!$B:$B,">="&$A6,Earnings!$B:$B,"<"&EDATE($A6,1))) -> 0 | H6: =IF(A6="","",SUMIFS(Earnings!$H:$H,Earnings!$B:$B,">="&$A6,Earnings!$B:$B,"<"&EDATE($A6,1))-SUMIFS(Spending!$G:$G,Spending!$A:$A,">="&$A6,Spending!$A:$A,"<"&EDATE($A6,1))) -> 0
A7: 46478 | B7: =IF(A7="","",SUMIFS(Earnings!$F:$F,Earnings!$B:$B,">="&$A7,Earnings!$B:$B,"<"&EDATE($A7,1))) -> 0 | C7: =IF(A7="","",SUMIFS(Earnings!$L:$L,Earnings!$K:$K,">="&$A7,Earnings!$K:$K,"<"&EDATE($A7,1))) -> 0 | D7: =IF(A7="","",SUMIFS(Spending!$E:$E,Spending!$A:$A,">="&$A7,Spending!$A:$A,"<"&EDATE($A7,1))) -> 0 | E7: =IF(A7="","",B7-D7) -> 0 | F7: =IF(OR(A7="",B7=0),"",E7/B7) | G7: =IF(A7="","",SUMIFS(Earnings!$I:$I,Earnings!$B:$B,">="&$A7,Earnings!$B:$B,"<"&EDATE($A7,1))-SUMIFS(Earnings!$L:$L,Earnings!$B:$B,">="&$A7,Earnings!$B:$B,"<"&EDATE($A7,1))) -> 0 | H7: =IF(A7="","",SUMIFS(Earnings!$H:$H,Earnings!$B:$B,">="&$A7,Earnings!$B:$B,"<"&EDATE($A7,1))-SUMIFS(Spending!$G:$G,Spending!$A:$A,">="&$A7,Spending!$A:$A,"<"&EDATE($A7,1))) -> 0
A8: 46508 | B8: =IF(A8="","",SUMIFS(Earnings!$F:$F,Earnings!$B:$B,">="&$A8,Earnings!$B:$B,"<"&EDATE($A8,1))) -> 0 | C8: =IF(A8="","",SUMIFS(Earnings!$L:$L,Earnings!$K:$K,">="&$A8,Earnings!$K:$K,"<"&EDATE($A8,1))) -> 0 | D8: =IF(A8="","",SUMIFS(Spending!$E:$E,Spending!$A:$A,">="&$A8,Spending!$A:$A,"<"&EDATE($A8,1))) -> 0 | E8: =IF(A8="","",B8-D8) -> 0 | F8: =IF(OR(A8="",B8=0),"",E8/B8) | G8: =IF(A8="","",SUMIFS(Earnings!$I:$I,Earnings!$B:$B,">="&$A8,Earnings!$B:$B,"<"&EDATE($A8,1))-SUMIFS(Earnings!$L:$L,Earnings!$B:$B,">="&$A8,Earnings!$B:$B,"<"&EDATE($A8,1))) -> 0 | H8: =IF(A8="","",SUMIFS(Earnings!$H:$H,Earnings!$B:$B,">="&$A8,Earnings!$B:$B,"<"&EDATE($A8,1))-SUMIFS(Spending!$G:$G,Spending!$A:$A,">="&$A8,Spending!$A:$A,"<"&EDATE($A8,1))) -> 0
A9: 46539 | B9: =IF(A9="","",SUMIFS(Earnings!$F:$F,Earnings!$B:$B,">="&$A9,Earnings!$B:$B,"<"&EDATE($A9,1))) -> 0 | C9: =IF(A9="","",SUMIFS(Earnings!$L:$L,Earnings!$K:$K,">="&$A9,Earnings!$K:$K,"<"&EDATE($A9,1))) -> 0 | D9: =IF(A9="","",SUMIFS(Spending!$E:$E,Spending!$A:$A,">="&$A9,Spending!$A:$A,"<"&EDATE($A9,1))) -> 0 | E9: =IF(A9="","",B9-D9) -> 0 | F9: =IF(OR(A9="",B9=0),"",E9/B9) | G9: =IF(A9="","",SUMIFS(Earnings!$I:$I,Earnings!$B:$B,">="&$A9,Earnings!$B:$B,"<"&EDATE($A9,1))-SUMIFS(Earnings!$L:$L,Earnings!$B:$B,">="&$A9,Earnings!$B:$B,"<"&EDATE($A9,1))) -> 0 | H9: =IF(A9="","",SUMIFS(Earnings!$H:$H,Earnings!$B:$B,">="&$A9,Earnings!$B:$B,"<"&EDATE($A9,1))-SUMIFS(Spending!$G:$G,Spending!$A:$A,">="&$A9,Spending!$A:$A,"<"&EDATE($A9,1))) -> 0
A10: 46569 | B10: =IF(A10="","",SUMIFS(Earnings!$F:$F,Earnings!$B:$B,">="&$A10,Earnings!$B:$B,"<"&EDATE($A10,1))) -> 0 | C10: =IF(A10="","",SUMIFS(Earnings!$L:$L,Earnings!$K:$K,">="&$A10,Earnings!$K:$K,"<"&EDATE($A10,1))) -> 0 | D10: =IF(A10="","",SUMIFS(Spending!$E:$E,Spending!$A:$A,">="&$A10,Spending!$A:$A,"<"&EDATE($A10,1))) -> 0 | E10: =IF(A10="","",B10-D10) -> 0 | F10: =IF(OR(A10="",B10=0),"",E10/B10) | G10: =IF(A10="","",SUMIFS(Earnings!$I:$I,Earnings!$B:$B,">="&$A10,Earnings!$B:$B,"<"&EDATE($A10,1))-SUMIFS(Earnings!$L:$L,Earnings!$B:$B,">="&$A10,Earnings!$B:$B,"<"&EDATE($A10,1))) -> 0 | H10: =IF(A10="","",SUMIFS(Earnings!$H:$H,Earnings!$B:$B,">="&$A10,Earnings!$B:$B,"<"&EDATE($A10,1))-SUMIFS(Spending!$G:$G,Spending!$A:$A,">="&$A10,Spending!$A:$A,"<"&EDATE($A10,1))) -> 0
A11: 46600 | B11: =IF(A11="","",SUMIFS(Earnings!$F:$F,Earnings!$B:$B,">="&$A11,Earnings!$B:$B,"<"&EDATE($A11,1))) -> 0 | C11: =IF(A11="","",SUMIFS(Earnings!$L:$L,Earnings!$K:$K,">="&$A11,Earnings!$K:$K,"<"&EDATE($A11,1))) -> 0 | D11: =IF(A11="","",SUMIFS(Spending!$E:$E,Spending!$A:$A,">="&$A11,Spending!$A:$A,"<"&EDATE($A11,1))) -> 0 | E11: =IF(A11="","",B11-D11) -> 0 | F11: =IF(OR(A11="",B11=0),"",E11/B11) | G11: =IF(A11="","",SUMIFS(Earnings!$I:$I,Earnings!$B:$B,">="&$A11,Earnings!$B:$B,"<"&EDATE($A11,1))-SUMIFS(Earnings!$L:$L,Earnings!$B:$B,">="&$A11,Earnings!$B:$B,"<"&EDATE($A11,1))) -> 0 | H11: =IF(A11="","",SUMIFS(Earnings!$H:$H,Earnings!$B:$B,">="&$A11,Earnings!$B:$B,"<"&EDATE($A11,1))-SUMIFS(Spending!$G:$G,Spending!$A:$A,">="&$A11,Spending!$A:$A,"<"&EDATE($A11,1))) -> 0
A12: 46631 | B12: =IF(A12="","",SUMIFS(Earnings!$F:$F,Earnings!$B:$B,">="&$A12,Earnings!$B:$B,"<"&EDATE($A12,1))) -> 0 | C12: =IF(A12="","",SUMIFS(Earnings!$L:$L,Earnings!$K:$K,">="&$A12,Earnings!$K:$K,"<"&EDATE($A12,1))) -> 0 | D12: =IF(A12="","",SUMIFS(Spending!$E:$E,Spending!$A:$A,">="&$A12,Spending!$A:$A,"<"&EDATE($A12,1))) -> 0 | E12: =IF(A12="","",B12-D12) -> 0 | F12: =IF(OR(A12="",B12=0),"",E12/B12) | G12: =IF(A12="","",SUMIFS(Earnings!$I:$I,Earnings!$B:$B,">="&$A12,Earnings!$B:$B,"<"&EDATE($A12,1))-SUMIFS(Earnings!$L:$L,Earnings!$B:$B,">="&$A12,Earnings!$B:$B,"<"&EDATE($A12,1))) -> 0 | H12: =IF(A12="","",SUMIFS(Earnings!$H:$H,Earnings!$B:$B,">="&$A12,Earnings!$B:$B,"<"&EDATE($A12,1))-SUMIFS(Spending!$G:$G,Spending!$A:$A,">="&$A12,Spending!$A:$A,"<"&EDATE($A12,1))) -> 0
A13: 46661 | B13: =IF(A13="","",SUMIFS(Earnings!$F:$F,Earnings!$B:$B,">="&$A13,Earnings!$B:$B,"<"&EDATE($A13,1))) -> 0 | C13: =IF(A13="","",SUMIFS(Earnings!$L:$L,Earnings!$K:$K,">="&$A13,Earnings!$K:$K,"<"&EDATE($A13,1))) -> 0 | D13: =IF(A13="","",SUMIFS(Spending!$E:$E,Spending!$A:$A,">="&$A13,Spending!$A:$A,"<"&EDATE($A13,1))) -> 0 | E13: =IF(A13="","",B13-D13) -> 0 | F13: =IF(OR(A13="",B13=0),"",E13/B13) | G13: =IF(A13="","",SUMIFS(Earnings!$I:$I,Earnings!$B:$B,">="&$A13,Earnings!$B:$B,"<"&EDATE($A13,1))-SUMIFS(Earnings!$L:$L,Earnings!$B:$B,">="&$A13,Earnings!$B:$B,"<"&EDATE($A13,1))) -> 0 | H13: =IF(A13="","",SUMIFS(Earnings!$H:$H,Earnings!$B:$B,">="&$A13,Earnings!$B:$B,"<"&EDATE($A13,1))-SUMIFS(Spending!$G:$G,Spending!$A:$A,">="&$A13,Spending!$A:$A,"<"&EDATE($A13,1))) -> 0
... A27: 47088 | B27: =IF(A27="","",SUMIFS(Earnings!$F:$F,Earnings!$B:$B,">="&$A27,Earnings!$B:$B,"<"&EDATE($A27,1))) -> 0 | C27: =IF(A27="","",SUMIFS(Earnings!$L:$L,Earnings!$K:$K,">="&$A27,Earnings!$K:$K,"<"&EDATE($A27,1))) -> 0 | D27: =IF(A27="","",SUMIFS(Spending!$E:$E,Spending!$A:$A,">="&$A27,Spending!$A:$A,"<"&EDATE($A27,1))) -> 0 | E27: =IF(A27="","",B27-D27) -> 0 | F27: =IF(OR(A27="",B27=0),"",E27/B27) | G27: =IF(A27="","",SUMIFS(Earnings!$I:$I,Earnings!$B:$B,">="&$A27,Earnings!$B:$B,"<"&EDATE($A27,1))-SUMIFS(Earnings!$L:$L,Earnings!$B:$B,">="&$A27,Earnings!$B:$B,"<"&EDATE($A27,1))) -> 0 | H27: =IF(A27="","",SUMIFS(Earnings!$H:$H,Earnings!$B:$B,">="&$A27,Earnings!$B:$B,"<"&EDATE($A27,1))-SUMIFS(Spending!$G:$G,Spending!$A:$A,">="&$A27,Spending!$A:$A,"<"&EDATE($A27,1))) -> 0

Sheet Growth Targets
A1: Month | B1: Sales reps | C1: Target new clients | D1: Target clients lost | E1: Target active clients | F1: Target revenue (AED / month) | G1: Actual new clients | H1: Actual active clients | I1: Actual revenue invoiced (AED) | J1: Revenue vs target | K1: Active clients vs target | L1: Notes
A2: 46327 | B2: =IF(A2="","",IFERROR(INDEX('Hiring Plan'!$C:$C,MATCH(A2,'Hiring Plan'!$A:$A,0)),0)) -> 1 | C2: =IF(A2="","",ROUND(B2*Settings!$B$5*(EDATE(A2,1)-DATE(2026,11,19))/7,0)) -> 3 | D2: =IF(A2="","",0) -> 0 | E2: =IF(A2="","",MAX(0,Settings!$B$8+C2-D2)) -> 3 | F2: =IF(A2="","",E2*Settings!$B$10) -> 22500 | I2: =IF(OR(A2="",A2>TODAY()),"",IFERROR(INDEX('Monthly Summary'!$B:$B,MATCH(A2,'Monthly Summary'!$A:$A,0)),"")) | J2: =IF(OR(A2="",F2=0,I2=""),"",I2/F2) | K2: =IF(OR(H2="",E2=0),"",H2/E2)
A3: 46357 | B3: =IF(A3="","",IFERROR(INDEX('Hiring Plan'!$C:$C,MATCH(A3,'Hiring Plan'!$A:$A,0)),0)) -> 1 | C3: =IF(A3="","",ROUND(B3*Settings!$B$5*Settings!$B$7,0)) -> 9 | D3: =IF(A3="","",ROUND(E2*Settings!$B$9,0)) -> 0 | E3: =IF(A3="","",MAX(0,E2+C3-D3)) -> 12 | F3: =IF(A3="","",E3*Settings!$B$10) -> 90000 | I3: =IF(OR(A3="",A3>TODAY()),"",IFERROR(INDEX('Monthly Summary'!$B:$B,MATCH(A3,'Monthly Summary'!$A:$A,0)),"")) | J3: =IF(OR(A3="",F3=0,I3=""),"",I3/F3) | K3: =IF(OR(H3="",E3=0),"",H3/E3)
A4: 46388 | B4: =IF(A4="","",IFERROR(INDEX('Hiring Plan'!$C:$C,MATCH(A4,'Hiring Plan'!$A:$A,0)),0)) -> 2 | C4: =IF(A4="","",ROUND(B4*Settings!$B$5*Settings!$B$7,0)) -> 17 | D4: =IF(A4="","",ROUND(E3*Settings!$B$9,0)) -> 1 | E4: =IF(A4="","",MAX(0,E3+C4-D4)) -> 28 | F4: =IF(A4="","",E4*Settings!$B$10) -> 210000 | I4: =IF(OR(A4="",A4>TODAY()),"",IFERROR(INDEX('Monthly Summary'!$B:$B,MATCH(A4,'Monthly Summary'!$A:$A,0)),"")) | J4: =IF(OR(A4="",F4=0,I4=""),"",I4/F4) | K4: =IF(OR(H4="",E4=0),"",H4/E4)
A5: 46419 | B5: =IF(A5="","",IFERROR(INDEX('Hiring Plan'!$C:$C,MATCH(A5,'Hiring Plan'!$A:$A,0)),0)) -> 2 | C5: =IF(A5="","",ROUND(B5*Settings!$B$5*Settings!$B$7,0)) -> 17 | D5: =IF(A5="","",ROUND(E4*Settings!$B$9,0)) -> 3 | E5: =IF(A5="","",MAX(0,E4+C5-D5)) -> 42 | F5: =IF(A5="","",E5*Settings!$B$10) -> 315000 | I5: =IF(OR(A5="",A5>TODAY()),"",IFERROR(INDEX('Monthly Summary'!$B:$B,MATCH(A5,'Monthly Summary'!$A:$A,0)),"")) | J5: =IF(OR(A5="",F5=0,I5=""),"",I5/F5) | K5: =IF(OR(H5="",E5=0),"",H5/E5)
A6: 46447 | B6: =IF(A6="","",IFERROR(INDEX('Hiring Plan'!$C:$C,MATCH(A6,'Hiring Plan'!$A:$A,0)),0)) -> 2 | C6: =IF(A6="","",ROUND(B6*Settings!$B$5*Settings!$B$7,0)) -> 17 | D6: =IF(A6="","",ROUND(E5*Settings!$B$9,0)) -> 4 | E6: =IF(A6="","",MAX(0,E5+C6-D6)) -> 55 | F6: =IF(A6="","",E6*Settings!$B$10) -> 412500 | I6: =IF(OR(A6="",A6>TODAY()),"",IFERROR(INDEX('Monthly Summary'!$B:$B,MATCH(A6,'Monthly Summary'!$A:$A,0)),"")) | J6: =IF(OR(A6="",F6=0,I6=""),"",I6/F6) | K6: =IF(OR(H6="",E6=0),"",H6/E6)
A7: 46478 | B7: =IF(A7="","",IFERROR(INDEX('Hiring Plan'!$C:$C,MATCH(A7,'Hiring Plan'!$A:$A,0)),0)) -> 3 | C7: =IF(A7="","",ROUND(B7*Settings!$B$5*Settings!$B$7,0)) -> 26 | D7: =IF(A7="","",ROUND(E6*Settings!$B$9,0)) -> 6 | E7: =IF(A7="","",MAX(0,E6+C7-D7)) -> 75 | F7: =IF(A7="","",E7*Settings!$B$10) -> 562500 | I7: =IF(OR(A7="",A7>TODAY()),"",IFERROR(INDEX('Monthly Summary'!$B:$B,MATCH(A7,'Monthly Summary'!$A:$A,0)),"")) | J7: =IF(OR(A7="",F7=0,I7=""),"",I7/F7) | K7: =IF(OR(H7="",E7=0),"",H7/E7)
