Workbook

Sheet Start Here
B1: YONTRO CRM
B2: One place for every lead – inbound or outbound – from first message to active client.
B4: HOW TO USE THIS SHEET
B5: White cells | C5: You type here. Most have dropdowns – pick from the list.
B6: Grey cells / grey headers | C6: Formulas. Don't type here – they calculate themselves.
B7: Row 2 on each tab | C7: An EXAMPLE row (grey italic). Overwrite or delete it once you start.
B8: Settings tab | C8: Edit dropdown lists, package prices and the rules (follow-up gap, decision window).
B9: Dates | C9: Columns marked 📅 open a calendar: double-click the cell and pick the day. Time columns have a dropdown arrow. If a calendar ever doesn't open, run the 'Add date pickers' script (see below).
B11: THE TABS
B12: Dashboard | C12: Daily, weekly and monthly numbers. Pick any day in the yellow cell (blank = today). Everything else is read only.
B13: Inbound | C13: Leads who came to us: website, WhatsApp, Instagram, referrals, walk-ins. Owner: Usama
B14: Outbound | C14: Leads we went after: Apollo, LinkedIn, Google Maps. Owner: Usama
B15: Clients | C15: Everyone who signed + paid: free video, decision window, refunds, active plan. Owner: Lianna
B16: Shoots | C16: Every shoot – free videos and plan shoots. Owner: Azeem
B17: Automations | C17: What connects to what (Make.com, Calendly, Apollo, Calendar). The setup checklist.
B19: THE PIPELINE
B20: Selling (Inbound / Outbound) | C20: New → Contacted → Replied → Meeting booked → Meeting held → Proposal sent → Contract signed + paid
C21: or → Closed – No response (after 4 follow-ups) / Lost
B22: Trial (Clients + Shoots) | C22: Signed + paid → Free video shot → Delivered → Decision window
B23: Outcome (Clients) | C23: Approves → Active · Says nothing → Active (plan goes ahead) · Backs out → Refund, keeps the video
B25: THE RULES WE AGREED
B26: Free video | C26: Only for clients who have signed the contract. As many as needed for onboarded clients.
B27: Payment | C27: Taken at signing.
B28: Backing out | C28: Client can back out after the free video if not satisfied → refund. They keep the free video.
B29: Silence after delivery | C29: Plan goes ahead – they have signed and paid.
B30: Ghosting (before contract) | C30: 4 follow-ups, 3 days apart, each adding new value. Then stop outreach → Closed – No response.
B31: Repeat refunds | C31: A business that was refunded before is flagged ⚠ – no second free video.
B32: Decision window | C32: NOT DECIDED YET – set to 3 working days as a placeholder (Settings tab, yellow cell).
B34: EACH PERSON'S DAY
B35: Usama | C35: Inbound + Outbound: filter Owner = Usama and Action flag. Clear OVERDUE first, then 'Follow up today'. Reply to new inbound within 1 hour.
B36: Azeem | C36: Shoots: filter Videographer = Azeem. Update Status and Delivered date the day it happens.
B37: Lianna | C37: Clients: work every 'Decision pending' row; onboard new signings; log refunds with a reason.
B38: Owner | C38: Dashboard once a week.
B40: IF THE CALENDARS DON'T OPEN (one-time fix, 2 minutes)
B41: 1 | C41: In the Google Sheet: Extensions → Apps Script.
B42: 2 | C42: Delete what's there, paste the code from yontro-crm/date-pickers.gs, click Save.
B43: 3 | C43: Choose addDatePickers in the toolbar and click Run (allow access the first time).
B44: 4 | C44: Back in the sheet, double-click any 📅 cell – the calendar opens.
B46: AFTER A FOLLOW-UP
B47: Update two cells | C47: Last contact date = today, and Follow-ups sent +1. The sheet works out the next due date.

Sheet Dashboard
B1: YONTRO · CRM DASHBOARD
B2: Updates automatically from the Inbound, Outbound, Clients and Shoots tabs. Only the yellow cell is yours to change.
B3: Day to view 📅 (double-click) | D3: Leave blank to always show today
B4: Showing | C4: =IF(C3="",TODAY(),C3) -> 46315
B5: Week starts (Monday) | C5: =C4-WEEKDAY(C4,2)+1 -> 46314
B6: Month starts | C6: =DATE(YEAR(C4),MONTH(C4),1) -> 46296
B8: DAILY · the day picked above | G8: PIPELINE BY STAGE · live
C9: Inbound | D9: Outbound | E9: Total | H9: Inbound | I9: Outbound | J9: Total
B10: New leads | C10: =COUNTIFS(Inbound!$B$2:$B$501,">="&$C$4,Inbound!$B$2:$B$501,"<"&$C$4+1,Inbound!$E$2:$E$501,"<>") -> 0 | D10: =COUNTIFS(Outbound!$B$2:$B$501,">="&$C$4,Outbound!$B$2:$B$501,"<"&$C$4+1,Outbound!$D$2:$D$501,"<>") -> 0 | E10: =C10+D10 -> 0 | G10: =Settings!A2 -> New | H10: =COUNTIF(Inbound!$R$2:$R$501,G10) -> 0 | I10: =COUNTIF(Outbound!$O$2:$O$501,G10) -> 0 | J10: =H10+I10 -> 0
B11: Leads contacted | C11: =COUNTIFS(Inbound!$S$2:$S$501,$C$4,Inbound!$E$2:$E$501,"<>") -> 0 | D11: =COUNTIFS(Outbound!$P$2:$P$501,$C$4,Outbound!$D$2:$D$501,"<>") -> 0 | E11: =C11+D11 -> 0 | G11: =Settings!A3 -> Contacted | H11: =COUNTIF(Inbound!$R$2:$R$501,G11) -> 0 | I11: =COUNTIF(Outbound!$O$2:$O$501,G11) -> 0 | J11: =H11+I11 -> 0
B12: Follow-ups due | C12: =COUNTIFS(Inbound!$U$2:$U$501,$C$4) -> 1 | D12: =COUNTIFS(Outbound!$R$2:$R$501,$C$4) -> 0 | E12: =C12+D12 -> 1 | G12: =Settings!A4 -> Replied | H12: =COUNTIF(Inbound!$R$2:$R$501,G12) -> 0 | I12: =COUNTIF(Outbound!$O$2:$O$501,G12) -> 1 | J12: =H12+I12 -> 1
B13: Sales meetings | C13: =COUNTIFS(Inbound!$V$2:$V$501,">="&$C$4,Inbound!$V$2:$V$501,"<"&$C$4+1) -> 0 | D13: =COUNTIFS(Outbound!$S$2:$S$501,">="&$C$4,Outbound!$S$2:$S$501,"<"&$C$4+1) -> 0 | E13: =C13+D13 -> 0 | G13: =Settings!A5 -> Meeting booked | H13: =COUNTIF(Inbound!$R$2:$R$501,G13) -> 0 | I13: =COUNTIF(Outbound!$O$2:$O$501,G13) -> 0 | J13: =H13+I13 -> 0
B14: Overdue follow-ups (live, as of today) | C14: =COUNTIF(Inbound!$AB$2:$AB$501,"OVERDUE follow-up") -> 0 | D14: =COUNTIF(Outbound!$Y$2:$Y$501,"OVERDUE follow-up") -> 1 | E14: =C14+D14 -> 1 | G14: =Settings!A6 -> Meeting held | H14: =COUNTIF(Inbound!$R$2:$R$501,G14) -> 0 | I14: =COUNTIF(Outbound!$O$2:$O$501,G14) -> 0 | J14: =H14+I14 -> 0
B15: Inbound leads still waiting for a first reply (live) | C15: =COUNTIFS(Inbound!$E$2:$E$501,"<>",Inbound!$N$2:$N$501,"") -> 0 | G15: =Settings!A7 -> Proposal sent | H15: =COUNTIF(Inbound!$R$2:$R$501,G15) -> 1 | I15: =COUNTIF(Outbound!$O$2:$O$501,G15) -> 0 | J15: =H15+I15 -> 1
B16: Shoots | C16: =COUNTIFS(Shoots!$E$2:$E$501,$C$4,Shoots!$A$2:$A$501,"<>") -> 0 | G16: =Settings!A8 -> Contract signed + paid | H16: =COUNTIF(Inbound!$R$2:$R$501,G16) -> 0 | I16: =COUNTIF(Outbound!$O$2:$O$501,G16) -> 0 | J16: =H16+I16 -> 0
B17: Free videos delivered | C17: =COUNTIFS(Clients!$N$2:$N$501,$C$4) -> 0 | G17: =Settings!A9 -> Closed – No response | H17: =COUNTIF(Inbound!$R$2:$R$501,G17) -> 0 | I17: =COUNTIF(Outbound!$O$2:$O$501,G17) -> 0 | J17: =H17+I17 -> 0
B18: Client decisions due | C18: =COUNTIFS(Clients!$O$2:$O$501,$C$4,Clients!$Q$2:$Q$501,"Decision*") -> 0 | G18: =Settings!A10 -> Lost | H18: =COUNTIF(Inbound!$R$2:$R$501,G18) -> 0 | I18: =COUNTIF(Outbound!$O$2:$O$501,G18) -> 0 | J18: =H18+I18 -> 0
B19: Contracts signed + paid | C19: =COUNTIFS(Clients!$J$2:$J$501,$C$4) -> 0 | G19: Total leads | H19: =SUM(H10:H18) -> 1 | I19: =SUM(I10:I18) -> 1 | J19: =SUM(J10:J18) -> 2
B20: Cash collected (AED) | C20: =SUMIFS(Clients!$K$2:$K$501,Clients!$J$2:$J$501,$C$4) -> 0
B21: Refunds waiting to be paid (live) | C21: =COUNTIF(Clients!$S$2:$S$501,"Requested")+COUNTIF(Clients!$S$2:$S$501,"Approved") -> 0 | G21: OPEN LEADS BY OWNER · live
H22: Open leads | I22: Actions due
B23: THIS WEEK · Monday to Sunday of the day picked | G23: =Settings!E2 -> Usama | H23: =COUNTIFS(Inbound!$Q$2:$Q$501,G23,Inbound!$E$2:$E$501,"<>")-COUNTIFS(Inbound!$Q$2:$Q$501,G23,Inbound!$R$2:$R$501,"Contract signed + paid")-COUNTIFS(Inbound!$Q$2:$Q$501,G23,Inbound!$R$2:$R$501,"Closed – No response")-COUNTIFS(Inbound!$Q$2:$Q$501,G23,Inbound!$R$2:$R$501,"Lost")+COUNTIFS(Outbound!$N$2:$N$501,G23,Outbound!$D$2:$D$501,"<>")-COUNTIFS(Outbound!$N$2:$N$501,G23,Outbound!$O$2:$O$501,"Contract signed + paid")-COUNTIFS(Outbound!$N$2:$N$501,G23,Outbound!$O$2:$O$501,"Closed – No response")-COUNTIFS(Outbound!$N$2:$N$501,G23,Outbound!$O$2:$O$501,"Lost") -> 2 | I23: =COUNTIFS(Inbound!$Q$2:$Q$501,G23,Inbound!$AB$2:$AB$501,"OVERDUE follow-up")+COUNTIFS(Inbound!$Q$2:$Q$501,G23,Inbound!$AB$2:$AB$501,"Follow up today")+COUNTIFS(Outbound!$N$2:$N$501,G23,Outbound!$Y$2:$Y$501,"OVERDUE follow-up")+COUNTIFS(Outbound!$N$2:$N$501,G23,Outbound!$Y$2:$Y$501,"Follow up today") -> 2
C24: Inbound | D24: Outbound | E24: Total | G24: =Settings!E3 -> Lianna | H24: =COUNTIFS(Inbound!$Q$2:$Q$501,G24,Inbound!$E$2:$E$501,"<>")-COUNTIFS(Inbound!$Q$2:$Q$501,G24,Inbound!$R$2:$R$501,"Contract signed + paid")-COUNTIFS(Inbound!$Q$2:$Q$501,G24,Inbound!$R$2:$R$501,"Closed – No response")-COUNTIFS(Inbound!$Q$2:$Q$501,G24,Inbound!$R$2:$R$501,"Lost")+COUNTIFS(Outbound!$N$2:$N$501,G24,Outbound!$D$2:$D$501,"<>")-COUNTIFS(Outbound!$N$2:$N$501,G24,Outbound!$O$2:$O$501,"Contract signed + paid")-COUNTIFS(Outbound!$N$2:$N$501,G24,Outbound!$O$2:$O$501,"Closed – No response")-COUNTIFS(Outbound!$N$2:$N$501,G24,Outbound!$O$2:$O$501,"Lost") -> 0 | I24: =COUNTIFS(Inbound!$Q$2:$Q$501,G24,Inbound!$AB$2:$AB$501,"OVERDUE follow-up")+COUNTIFS(Inbound!$Q$2:$Q$501,G24,Inbound!$AB$2:$AB$501,"Follow up today")+COUNTIFS(Outbound!$N$2:$N$501,G24,Outbound!$Y$2:$Y$501,"OVERDUE follow-up")+COUNTIFS(Outbound!$N$2:$N$501,G24,Outbound!$Y$2:$Y$501,"Follow up today") -> 0
B25: Leads added | C25: =COUNTIFS(Inbound!$B$2:$B$501,">="&$C$5,Inbound!$B$2:$B$501,"<"&$C$5+7,Inbound!$E$2:$E$501,"<>") -> 0 | D25: =COUNTIFS(Outbound!$B$2:$B$501,">="&$C$5,Outbound!$B$2:$B$501,"<"&$C$5+7,Outbound!$D$2:$D$501,"<>") -> 0 | E25: =C25+D25 -> 0 | G25: =Settings!E4 -> Azeem | H25: =COUNTIFS(Inbound!$Q$2:$Q$501,G25,Inbound!$E$2:$E$501,"<>")-COUNTIFS(Inbound!$Q$2:$Q$501,G25,Inbound!$R$2:$R$501,"Contract signed + paid")-COUNTIFS(Inbound!$Q$2:$Q$501,G25,Inbound!$R$2:$R$501,"Closed – No response")-COUNTIFS(Inbound!$Q$2:$Q$501,G25,Inbound!$R$2:$R$501,"Lost")+COUNTIFS(Outbound!$N$2:$N$501,G25,Outbound!$D$2:$D$501,"<>")-COUNTIFS(Outbound!$N$2:$N$501,G25,Outbound!$O$2:$O$501,"Contract signed + paid")-COUNTIFS(Outbound!$N$2:$N$501,G25,Outbound!$O$2:$O$501,"Closed – No response")-COUNTIFS(Outbound!$N$2:$N$501,G25,Outbound!$O$2:$O$501,"Lost") -> 0 | I25: =COUNTIFS(Inbound!$Q$2:$Q$501,G25,Inbound!$AB$2:$AB$501,"OVERDUE follow-up")+COUNTIFS(Inbound!$Q$2:$Q$501,G25,Inbound!$AB$2:$AB$501,"Follow up today")+COUNTIFS(Outbound!$N$2:$N$501,G25,Outbound!$Y$2:$Y$501,"OVERDUE follow-up")+COUNTIFS(Outbound!$N$2:$N$501,G25,Outbound!$Y$2:$Y$501,"Follow up today") -> 0
B26: Sales meetings | C26: =COUNTIFS(Inbound!$V$2:$V$501,">="&$C$5,Inbound!$V$2:$V$501,"<"&$C$5+7) -> 0 | D26: =COUNTIFS(Outbound!$S$2:$S$501,">="&$C$5,Outbound!$S$2:$S$501,"<"&$C$5+7) -> 0 | E26: =C26+D26 -> 0 | G26: =Settings!E5 -> Owner | H26: =COUNTIFS(Inbound!$Q$2:$Q$501,G26,Inbound!$E$2:$E$501,"<>")-COUNTIFS(Inbound!$Q$2:$Q$501,G26,Inbound!$R$2:$R$501,"Contract signed + paid")-COUNTIFS(Inbound!$Q$2:$Q$501,G26,Inbound!$R$2:$R$501,"Closed – No response")-COUNTIFS(Inbound!$Q$2:$Q$501,G26,Inbound!$R$2:$R$501,"Lost")+COUNTIFS(Outbound!$N$2:$N$501,G26,Outbound!$D$2:$D$501,"<>")-COUNTIFS(Outbound!$N$2:$N$501,G26,Outbound!$O$2:$O$501,"Contract signed + paid")-COUNTIFS(Outbound!$N$2:$N$501,G26,Outbound!$O$2:$O$501,"Closed – No response")-COUNTIFS(Outbound!$N$2:$N$501,G26,Outbound!$O$2:$O$501,"Lost") -> 0 | I26: =COUNTIFS(Inbound!$Q$2:$Q$501,G26,Inbound!$AB$2:$AB$501,"OVERDUE follow-up")+COUNTIFS(Inbound!$Q$2:$Q$501,G26,Inbound!$AB$2:$AB$501,"Follow up today")+COUNTIFS(Outbound!$N$2:$N$501,G26,Outbound!$Y$2:$Y$501,"OVERDUE follow-up")+COUNTIFS(Outbound!$N$2:$N$501,G26,Outbound!$Y$2:$Y$501,"Follow up today") -> 0
B27: Follow-ups due today or overdue (live) | C27: =COUNTIF(Inbound!$AB$2:$AB$501,"Follow up today")+COUNTIF(Inbound!$AB$2:$AB$501,"OVERDUE follow-up") -> 1 | D27: =COUNTIF(Outbound!$Y$2:$Y$501,"Follow up today")+COUNTIF(Outbound!$Y$2:$Y$501,"OVERDUE follow-up") -> 1 | E27: =C27+D27 -> 2
B28: Leads to close (4 follow-ups sent) | C28: =COUNTIF(Inbound!$AB$2:$AB$501,"Close – 4 follow-ups sent") -> 0 | D28: =COUNTIF(Outbound!$Y$2:$Y$501,"Close – 4 follow-ups sent") -> 0 | E28: =C28+D28 -> 0
B29: Avg inbound response time (hrs, all time) | C29: =IFERROR(AVERAGE(Inbound!$P$2:$P$501),"-") -> 0.5 | G29: LEADS BY SOURCE (ALL TIME)
H30: Leads | I30: Signed
B31: THIS MONTH · of the day picked | G31: In · Website form | H31: =COUNTIF(Inbound!$D$2:$D$501,"Website form") -> 1 | I31: =COUNTIFS(Inbound!$D$2:$D$501,"Website form",Inbound!$R$2:$R$501,"Contract signed + paid") -> 0
B32: Contracts signed + paid | C32: =COUNTIFS(Clients!$J$2:$J$501,">="&$C$6,Clients!$J$2:$J$501,"<"&EDATE($C$6,1)) -> 1 | G32: In · WhatsApp | H32: =COUNTIF(Inbound!$D$2:$D$501,"WhatsApp") -> 0 | I32: =COUNTIFS(Inbound!$D$2:$D$501,"WhatsApp",Inbound!$R$2:$R$501,"Contract signed + paid") -> 0
B33: Cash collected at signing (AED) | C33: =SUMIFS(Clients!$K$2:$K$501,Clients!$J$2:$J$501,">="&$C$6,Clients!$J$2:$J$501,"<"&EDATE($C$6,1)) -> 7875 | G33: In · Instagram DM | H33: =COUNTIF(Inbound!$D$2:$D$501,"Instagram DM") -> 0 | I33: =COUNTIFS(Inbound!$D$2:$D$501,"Instagram DM",Inbound!$R$2:$R$501,"Contract signed + paid") -> 0
B34: Refunds paid (count) | C34: =COUNTIFS(Clients!$S$2:$S$501,"Paid",Clients!$U$2:$U$501,">="&$C$6,Clients!$U$2:$U$501,"<"&EDATE($C$6,1)) -> 0 | G34: In · Referral | H34: =COUNTIF(Inbound!$D$2:$D$501,"Referral") -> 0 | I34: =COUNTIFS(Inbound!$D$2:$D$501,"Referral",Inbound!$R$2:$R$501,"Contract signed + paid") -> 0
B35: Refunds paid (AED) | C35: =SUMIFS(Clients!$T$2:$T$501,Clients!$S$2:$S$501,"Paid",Clients!$U$2:$U$501,">="&$C$6,Clients!$U$2:$U$501,"<"&EDATE($C$6,1)) -> 0 | G35: In · Walk-in | H35: =COUNTIF(Inbound!$D$2:$D$501,"Walk-in") -> 0 | I35: =COUNTIFS(Inbound!$D$2:$D$501,"Walk-in",Inbound!$R$2:$R$501,"Contract signed + paid") -> 0
G36: In · Phone call | H36: =COUNTIF(Inbound!$D$2:$D$501,"Phone call") -> 0 | I36: =COUNTIFS(Inbound!$D$2:$D$501,"Phone call",Inbound!$R$2:$R$501,"Contract signed + paid") -> 0
B37: CLIENTS · live | G37: In · Other | H37: =COUNTIF(Inbound!$D$2:$D$501,"Other") -> 0 | I37: =COUNTIFS(Inbound!$D$2:$D$501,"Other",Inbound!$R$2:$R$501,"Contract signed + paid") -> 0
B38: Active clients | C38: =COUNTIF(Clients!$Q$2:$Q$501,"Active*") -> 0 | G38: Out · Apollo | H38: =COUNTIF(Outbound!$C$2:$C$501,"Apollo") -> 1 | I38: =COUNTIFS(Outbound!$C$2:$C$501,"Apollo",Outbound!$O$2:$O$501,"Contract signed + paid") -> 0
B39: Monthly recurring revenue (AED, ex VAT) | C39: =SUMIFS(Clients!$I$2:$I$501,Clients!$Q$2:$Q$501,"Active*") -> 0 | G39: Out · LinkedIn | H39: =COUNTIF(Outbound!$C$2:$C$501,"LinkedIn") -> 0 | I39: =COUNTIFS(Outbound!$C$2:$C$501,"LinkedIn",Outbound!$O$2:$O$501,"Contract signed + paid") -> 0
B40: Decisions pending | C40: =COUNTIF(Clients!$Q$2:$Q$501,"Decision*") -> 1 | G40: Out · Google Maps | H40: =COUNTIF(Outbound!$C$2:$C$501,"Google Maps") -> 0 | I40: =COUNTIFS(Outbound!$C$2:$C$501,"Google Maps",Outbound!$O$2:$O$501,"Contract signed + paid") -> 0
B41: Free videos to schedule / in production | C41: =COUNTIF(Clients!$Q$2:$Q$501,"Schedule free video")+COUNTIF(Clients!$Q$2:$Q$501,"Free video in production") -> 0 | G41: Out · Instagram research | H41: =COUNTIF(Outbound!$C$2:$C$501,"Instagram research") -> 0 | I41: =COUNTIFS(Outbound!$C$2:$C$501,"Instagram research",Outbound!$O$2:$O$501,"Contract signed + paid") -> 0
...

Sheet Inbound
A1: Lead ID | B1: Date received 📅 | C1: Time received | D1: Source | E1: Business name | F1: Industry | G1: Contact name | H1: Role | I1: Phone / WhatsApp | J1: Email | K1: Instagram | L1: Area | M1: Wants more of | N1: First response date 📅 | O1: First response time | P1: Response time (hrs) | Q1: Owner | R1: Stage | S1: Last contact date 📅 | T1: Follow-ups sent (0-4) | U1: Next follow-up due | V1: Meeting date 📅 | W1: Meeting time | X1: Package discussed | Y1: Lost / closed reason | Z1: Notes | AA1: Days open | AB1: Action flag
A2: IN-0001 | B2: 46310 | C2: 0.41666667 | D2: Website form | E2: Pulse Fitness Club (EXAMPLE) | F2: Fitness / wellness | G2: Sara M. | H2: Owner | I2: +971 50 000 0000 | J2: sara@example.com | K2: @pulse.fitness.jlt | L2: JLT | M2: Enquiries and bookings | N2: 46310 | O2: 0.4375 | P2: =IF(OR(B2="",N2=""),"",ROUND(((N2+N(O2))-(B2+N(C2)))*24,1)) -> 0.5 | Q2: Usama | R2: Proposal sent | S2: 46312 | T2: 1 | U2: =IF(OR(E2="",S2="",OR(R2="Contract signed + paid",R2="Closed – No response",R2="Lost"),N(T2)>=Settings!$S$3),"",S2+Settings!$S$2) -> 46315 | V2: 46311 | W2: 0.625 | X2: Growth | Z2: Example row – overwrite or delete. | AA2: =IF(OR(E2="",B2=""),"",INT(TODAY()-B2)) -> 5 | AB2: =IF(E2="","",IF(OR(COUNTIFS(Clients!$C$2:$C$501,E2,Clients!$S$2:$S$501,"Paid")>0,AND(I2<>"",COUNTIFS(Clients!$E$2:$E$501,I2,Clients!$S$2:$S$501,"Paid")>0)),"⚠ Refunded before – no free video",IF(OR(R2="Contract signed + paid",R2="Closed – No response",R2="Lost"),"",IF(R2="","Set a stage",IF(N(T2)>=Settings!$S$3,"Close – 4 follow-ups sent",IF(U2="",IF(S2="","Make first contact",""),IF(TODAY()>U2,"OVERDUE follow-up",IF(TODAY()=U2,"Follow up today","")))))))) -> Follow up today
P3: =IF(OR(B3="",N3=""),"",ROUND(((N3+N(O3))-(B3+N(C3)))*24,1)) | U3: =IF(OR(E3="",S3="",OR(R3="Contract signed + paid",R3="Closed – No response",R3="Lost"),N(T3)>=Settings!$S$3),"",S3+Settings!$S$2) | AA3: =IF(OR(E3="",B3=""),"",INT(TODAY()-B3)) | AB3: =IF(E3="","",IF(OR(COUNTIFS(Clients!$C$2:$C$501,E3,Clients!$S$2:$S$501,"Paid")>0,AND(I3<>"",COUNTIFS(Clients!$E$2:$E$501,I3,Clients!$S$2:$S$501,"Paid")>0)),"⚠ Refunded before – no free video",IF(OR(R3="Contract signed + paid",R3="Closed – No response",R3="Lost"),"",IF(R3="","Set a stage",IF(N(T3)>=Settings!$S$3,"Close – 4 follow-ups sent",IF(U3="",IF(S3="","Make first contact",""),IF(TODAY()>U3,"OVERDUE follow-up",IF(TODAY()=U3,"Follow up today",""))))))))
P4: =IF(OR(B4="",N4=""),"",ROUND(((N4+N(O4))-(B4+N(C4)))*24,1)) | U4: =IF(OR(E4="",S4="",OR(R4="Contract signed + paid",R4="Closed – No response",R4="Lost"),N(T4)>=Settings!$S$3),"",S4+Settings!$S$2) | AA4: =IF(OR(E4="",B4=""),"",INT(TODAY()-B4)) | AB4: =IF(E4="","",IF(OR(COUNTIFS(Clients!$C$2:$C$501,E4,Clients!$S$2:$S$501,"Paid")>0,AND(I4<>"",COUNTIFS(Clients!$E$2:$E$501,I4,Clients!$S$2:$S$501,"Paid")>0)),"⚠ Refunded before – no free video",IF(OR(R4="Contract signed + paid",R4="Closed – No response",R4="Lost"),"",IF(R4="","Set a stage",IF(N(T4)>=Settings!$S$3,"Close – 4 follow-ups sent",IF(U4="",IF(S4="","Make first contact",""),IF(TODAY()>U4,"OVERDUE follow-up",IF(TODAY()=U4,"Follow up today",""))))))))
P5: =IF(OR(B5="",N5=""),"",ROUND(((N5+N(O5))-(B5+N(C5)))*24,1)) | U5: =IF(OR(E5="",S5="",OR(R5="Contract signed + paid",R5="Closed – No response",R5="Lost"),N(T5)>=Settings!$S$3),"",S5+Settings!$S$2) | AA5: =IF(OR(E5="",B5=""),"",INT(TODAY()-B5)) | AB5: =IF(E5="","",IF(OR(COUNTIFS(Clients!$C$2:$C$501,E5,Clients!$S$2:$S$501,"Paid")>0,AND(I5<>"",COUNTIFS(Clients!$E$2:$E$501,I5,Clients!$S$2:$S$501,"Paid")>0)),"⚠ Refunded before – no free video",IF(OR(R5="Contract signed + paid",R5="Closed – No response",R5="Lost"),"",IF(R5="","Set a stage",IF(N(T5)>=Settings!$S$3,"Close – 4 follow-ups sent",IF(U5="",IF(S5="","Make first contact",""),IF(TODAY()>U5,"OVERDUE follow-up",IF(TODAY()=U5,"Follow up today",""))))))))
P6: =IF(OR(B6="",N6=""),"",ROUND(((N6+N(O6))-(B6+N(C6)))*24,1)) | U6: =IF(OR(E6="",S6="",OR(R6="Contract signed + paid",R6="Closed – No response",R6="Lost"),N(T6)>=Settings!$S$3),"",S6+Settings!$S$2) | AA6: =IF(OR(E6="",B6=""),"",INT(TODAY()-B6)) | AB6: =IF(E6="","",IF(OR(COUNTIFS(Clients!$C$2:$C$501,E6,Clients!$S$2:$S$501,"Paid")>0,AND(I6<>"",COUNTIFS(Clients!$E$2:$E$501,I6,Clients!$S$2:$S$501,"Paid")>0)),"⚠ Refunded before – no free video",IF(OR(R6="Contract signed + paid",R6="Closed – No response",R6="Lost"),"",IF(R6="","Set a stage",IF(N(T6)>=Settings!$S$3,"Close – 4 follow-ups sent",IF(U6="",IF(S6="","Make first contact",""),IF(TODAY()>U6,"OVERDUE follow-up",IF(TODAY()=U6,"Follow up today",""))))))))
P7: =IF(OR(B7="",N7=""),"",ROUND(((N7+N(O7))-(B7+N(C7)))*24,1)) | U7: =IF(OR(E7="",S7="",OR(R7="Contract signed + paid",R7="Closed – No response",R7="Lost"),N(T7)>=Settings!$S$3),"",S7+Settings!$S$2) | AA7: =IF(OR(E7="",B7=""),"",INT(TODAY()-B7)) | AB7: =IF(E7="","",IF(OR(COUNTIFS(Clients!$C$2:$C$501,E7,Clients!$S$2:$S$501,"Paid")>0,AND(I7<>"",COUNTIFS(Clients!$E$2:$E$501,I7,Clients!$S$2:$S$501,"Paid")>0)),"⚠ Refunded before – no free video",IF(OR(R7="Contract signed + paid",R7="Closed – No response",R7="Lost"),"",IF(R7="","Set a stage",IF(N(T7)>=Settings!$S$3,"Close – 4 follow-ups sent",IF(U7="",IF(S7="","Make first contact",""),IF(TODAY()>U7,"OVERDUE follow-up",IF(TODAY()=U7,"Follow up today",""))))))))
P8: =IF(OR(B8="",N8=""),"",ROUND(((N8+N(O8))-(B8+N(C8)))*24,1)) | U8: =IF(OR(E8="",S8="",OR(R8="Contract signed + paid",R8="Closed – No response",R8="Lost"),N(T8)>=Settings!$S$3),"",S8+Settings!$S$2) | AA8: =IF(OR(E8="",B8=""),"",INT(TODAY()-B8)) | AB8: =IF(E8="","",IF(OR(COUNTIFS(Clients!$C$2:$C$501,E8,Clients!$S$2:$S$501,"Paid")>0,AND(I8<>"",COUNTIFS(Clients!$E$2:$E$501,I8,Clients!$S$2:$S$501,"Paid")>0)),"⚠ Refunded before – no free video",IF(OR(R8="Contract signed + paid",R8="Closed – No response",R8="Lost"),"",IF(R8="","Set a stage",IF(N(T8)>=Settings!$S$3,"Close – 4 follow-ups sent",IF(U8="",IF(S8="","Make first contact",""),IF(TODAY()>U8,"OVERDUE follow-up",IF(TODAY()=U8,"Follow up today",""))))))))
P9: =IF(OR(B9="",N9=""),"",ROUND(((N9+N(O9))-(B9+N(C9)))*24,1)) | U9: =IF(OR(E9="",S9="",OR(R9="Contract signed + paid",R9="Closed – No response",R9="Lost"),N(T9)>=Settings!$S$3),"",S9+Settings!$S$2) | AA9: =IF(OR(E9="",B9=""),"",INT(TODAY()-B9)) | AB9: =IF(E9="","",IF(OR(COUNTIFS(Clients!$C$2:$C$501,E9,Clients!$S$2:$S$501,"Paid")>0,AND(I9<>"",COUNTIFS(Clients!$E$2:$E$501,I9,Clients!$S$2:$S$501,"Paid")>0)),"⚠ Refunded before – no free video",IF(OR(R9="Contract signed + paid",R9="Closed – No response",R9="Lost"),"",IF(R9="","Set a stage",IF(N(T9)>=Settings!$S$3,"Close – 4 follow-ups sent",IF(U9="",IF(S9="","Make first contact",""),IF(TODAY()>U9,"OVERDUE follow-up",IF(TODAY()=U9,"Follow up today",""))))))))
P10: =IF(OR(B10="",N10=""),"",ROUND(((N10+N(O10))-(B10+N(C10)))*24,1)) | U10: =IF(OR(E10="",S10="",OR(R10="Contract signed + paid",R10="Closed – No response",R10="Lost"),N(T10)>=Settings!$S$3),"",S10+Settings!$S$2) | AA10: =IF(OR(E10="",B10=""),"",INT(TODAY()-B10)) | AB10: =IF(E10="","",IF(OR(COUNTIFS(Clients!$C$2:$C$501,E10,Clients!$S$2:$S$501,"Paid")>0,AND(I10<>"",COUNTIFS(Clients!$E$2:$E$501,I10,Clients!$S$2:$S$501,"Paid")>0)),"⚠ Refunded before – no free video",IF(OR(R10="Contract signed + paid",R10="Closed – No response",R10="Lost"),"",IF(R10="","Set a stage",IF(N(T10)>=Settings!$S$3,"Close – 4 follow-ups sent",IF(U10="",IF(S10="","Make first contact",""),IF(TODAY()>U10,"OVERDUE follow-up",IF(TODAY()=U10,"Follow up today",""))))))))
P11: =IF(OR(B11="",N11=""),"",ROUND(((N11+N(O11))-(B11+N(C11)))*24,1)) | U11: =IF(OR(E11="",S11="",OR(R11="Contract signed + paid",R11="Closed – No response",R11="Lost"),N(T11)>=Settings!$S$3),"",S11+Settings!$S$2) | AA11: =IF(OR(E11="",B11=""),"",INT(TODAY()-B11)) | AB11: =IF(E11="","",IF(OR(COUNTIFS(Clients!$C$2:$C$501,E11,Clients!$S$2:$S$501,"Paid")>0,AND(I11<>"",COUNTIFS(Clients!$E$2:$E$501,I11,Clients!$S$2:$S$501,"Paid")>0)),"⚠ Refunded before – no free video",IF(OR(R11="Contract signed + paid",R11="Closed – No response",R11="Lost"),"",IF(R11="","Set a stage",IF(N(T11)>=Settings!$S$3,"Close – 4 follow-ups sent",IF(U11="",IF(S11="","Make first contact",""),IF(TODAY()>U11,"OVERDUE follow-up",IF(TODAY()=U11,"Follow up today",""))))))))
P12: =IF(OR(B12="",N12=""),"",ROUND(((N12+N(O12))-(B12+N(C12)))*24,1)) | U12: =IF(OR(E12="",S12="",OR(R12="Contract signed + paid",R12="Closed – No response",R12="Lost"),N(T12)>=Settings!$S$3),"",S12+Settings!$S$2) | AA12: =IF(OR(E12="",B12=""),"",INT(TODAY()-B12)) | AB12: =IF(E12="","",IF(OR(COUNTIFS(Clients!$C$2:$C$501,E12,Clients!$S$2:$S$501,"Paid")>0,AND(I12<>"",COUNTIFS(Clients!$E$2:$E$501,I12,Clients!$S$2:$S$501,"Paid")>0)),"⚠ Refunded before – no free video",IF(OR(R12="Contract signed + paid",R12="Closed – No response",R12="Lost"),"",IF(R12="","Set a stage",IF(N(T12)>=Settings!$S$3,"Close – 4 follow-ups sent",IF(U12="",IF(S12="","Make first contact",""),IF(TODAY()>U12,"OVERDUE follow-up",IF(TODAY()=U12,"Follow up today",""))))))))
P13: =IF(OR(B13="",N13=""),"",ROUND(((N13+N(O13))-(B13+N(C13)))*24,1)) | U13: =IF(OR(E13="",S13="",OR(R13="Contract signed + paid",R13="Closed – No response",R13="Lost"),N(T13)>=Settings!$S$3),"",S13+Settings!$S$2) | AA13: =IF(OR(E13="",B13=""),"",INT(TODAY()-B13)) | AB13: =IF(E13="","",IF(OR(COUNTIFS(Clients!$C$2:$C$501,E13,Clients!$S$2:$S$501,"Paid")>0,AND(I13<>"",COUNTIFS(Clients!$E$2:$E$501,I13,Clients!$S$2:$S$501,"Paid")>0)),"⚠ Refunded before – no free video",IF(OR(R13="Contract signed + paid",R13="Closed – No response",R13="Lost"),"",IF(R13="","Set a stage",IF(N(T13)>=Settings!$S$3,"Close – 4 follow-ups sent",IF(U13="",IF(S13="","Make first contact",""),IF(TODAY()>U13,"OVERDUE follow-up",IF(TODAY()=U13,"Follow up today",""))))))))
P14: =IF(OR(B14="",N14=""),"",ROUND(((N14+N(O14))-(B14+N(C14)))*24,1)) | U14: =IF(OR(E14="",S14="",OR(R14="Contract signed + paid",R14="Closed – No response",R14="Lost"),N(T14)>=Settings!$S$3),"",S14+Settings!$S$2) | AA14: =IF(OR(E14="",B14=""),"",INT(TODAY()-B14)) | AB14: =IF(E14="","",IF(OR(COUNTIFS(Clients!$C$2:$C$501,E14,Clients!$S$2:$S$501,"Paid")>0,AND(I14<>"",COUNTIFS(Clients!$E$2:$E$501,I14,Clients!$S$2:$S$501,"Paid")>0)),"⚠ Refunded before – no free video",IF(OR(R14="Contract signed + paid",R14="Closed – No response",R14="Lost"),"",IF(R14="","Set a stage",IF(N(T14)>=Settings!$S$3,"Close – 4 follow-ups sent",IF(U14="",IF(S14="","Make first contact",""),IF(TODAY()>U14,"OVERDUE follow-up",IF(TODAY()=U14,"Follow up today",""))))))))
... P501: =IF(OR(B501="",N501=""),"",ROUND(((N501+N(O501))-(B501+N(C501)))*24,1)) | U501: =IF(OR(E501="",S501="",OR(R501="Contract signed + paid",R501="Closed – No response",R501="Lost"),N(T501)>=Settings!$S$3),"",S501+Settings!$S$2) | AA501: =IF(OR(E501="",B501=""),"",INT(TODAY()-B501)) | AB501: =IF(E501="","",IF(OR(COUNTIFS(Clients!$C$2:$C$501,E501,Clients!$S$2:$S$501,"Paid")>0,AND(I501<>"",COUNTIFS(Clients!$E$2:$E$501,I501,Clients!$S$2:$S$501,"Paid")>0)),"⚠ Refunded before – no free video",IF(OR(R501="Contract signed + paid",R501="Closed – No response",R501="Lost"),"",IF(R501="","Set a stage",IF(N(T501)>=Settings!$S$3,"Close – 4 follow-ups sent",IF(U501="",IF(S501="","Make first contact",""),IF(TODAY()>U501,"OVERDUE follow-up",IF(TODAY()=U501,"Follow up today",""))))))))

Sheet Outbound
A1: Lead ID | B1: Date added 📅 | C1: Source | D1: Business name | E1: Industry | F1: Contact name | G1: Role | H1: Phone / WhatsApp | I1: Email | J1: Instagram | K1: LinkedIn | L1: Area | M1: Apollo list / campaign | N1: Owner | O1: Stage | P1: Last contact date 📅 | Q1: Follow-ups sent (0-4) | R1: Next follow-up due | S1: Meeting date 📅 | T1: Meeting time | U1: Package discussed | V1: Lost / closed reason | W1: Notes | X1: Days open | Y1: Action flag
A2: OUT-0001 | B2: 46308 | C2: Apollo | D2: Marina Bites Café (EXAMPLE) | E2: Hospitality / F&B | F2: Omar K. | G2: Marketing manager | H2: +971 55 000 0000 | I2: omar@example.com | J2: @marinabites | K2: linkedin.com/in/example | L2: Dubai Marina | M2: F&B – Marina – Oct 26 | N2: Usama | O2: Replied | P2: 46311 | Q2: 0 | R2: =IF(OR(D2="",P2="",OR(O2="Contract signed + paid",O2="Closed – No response",O2="Lost"),N(Q2)>=Settings!$S$3),"",P2+Settings!$S$2) -> 46314 | U2: Launch | W2: Example row – overwrite or delete. | X2: =IF(OR(D2="",B2=""),"",INT(TODAY()-B2)) -> 7 | Y2: =IF(D2="","",IF(OR(COUNTIFS(Clients!$C$2:$C$501,D2,Clients!$S$2:$S$501,"Paid")>0,AND(H2<>"",COUNTIFS(Clients!$E$2:$E$501,H2,Clients!$S$2:$S$501,"Paid")>0)),"⚠ Refunded before – no free video",IF(OR(O2="Contract signed + paid",O2="Closed – No response",O2="Lost"),"",IF(O2="","Set a stage",IF(N(Q2)>=Settings!$S$3,"Close – 4 follow-ups sent",IF(R2="",IF(P2="","Make first contact",""),IF(TODAY()>R2,"OVERDUE follow-up",IF(TODAY()=R2,"Follow up today","")))))))) -> OVERDUE follow-up
R3: =IF(OR(D3="",P3="",OR(O3="Contract signed + paid",O3="Closed – No response",O3="Lost"),N(Q3)>=Settings!$S$3),"",P3+Settings!$S$2) | X3: =IF(OR(D3="",B3=""),"",INT(TODAY()-B3)) | Y3: =IF(D3="","",IF(OR(COUNTIFS(Clients!$C$2:$C$501,D3,Clients!$S$2:$S$501,"Paid")>0,AND(H3<>"",COUNTIFS(Clients!$E$2:$E$501,H3,Clients!$S$2:$S$501,"Paid")>0)),"⚠ Refunded before – no free video",IF(OR(O3="Contract signed + paid",O3="Closed – No response",O3="Lost"),"",IF(O3="","Set a stage",IF(N(Q3)>=Settings!$S$3,"Close – 4 follow-ups sent",IF(R3="",IF(P3="","Make first contact",""),IF(TODAY()>R3,"OVERDUE follow-up",IF(TODAY()=R3,"Follow up today",""))))))))
R4: =IF(OR(D4="",P4="",OR(O4="Contract signed + paid",O4="Closed – No response",O4="Lost"),N(Q4)>=Settings!$S$3),"",P4+Settings!$S$2) | X4: =IF(OR(D4="",B4=""),"",INT(TODAY()-B4)) | Y4: =IF(D4="","",IF(OR(COUNTIFS(Clients!$C$2:$C$501,D4,Clients!$S$2:$S$501,"Paid")>0,AND(H4<>"",COUNTIFS(Clients!$E$2:$E$501,H4,Clients!$S$2:$S$501,"Paid")>0)),"⚠ Refunded before – no free video",IF(OR(O4="Contract signed + paid",O4="Closed – No response",O4="Lost"),"",IF(O4="","Set a stage",IF(N(Q4)>=Settings!$S$3,"Close – 4 follow-ups sent",IF(R4="",IF(P4="","Make first contact",""),IF(TODAY()>R4,"OVERDUE follow-up",IF(TODAY()=R4,"Follow up today",""))))))))
R5: =IF(OR(D5="",P5="",OR(O5="Contract signed + paid",O5="Closed – No response",O5="Lost"),N(Q5)>=Settings!$S$3),"",P5+Settings!$S$2) | X5: =IF(OR(D5="",B5=""),"",INT(TODAY()-B5)) | Y5: =IF(D5="","",IF(OR(COUNTIFS(Clients!$C$2:$C$501,D5,Clients!$S$2:$S$501,"Paid")>0,AND(H5<>"",COUNTIFS(Clients!$E$2:$E$501,H5,Clients!$S$2:$S$501,"Paid")>0)),"⚠ Refunded before – no free video",IF(OR(O5="Contract signed + paid",O5="Closed – No response",O5="Lost"),"",IF(O5="","Set a stage",IF(N(Q5)>=Settings!$S$3,"Close – 4 follow-ups sent",IF(R5="",IF(P5="","Make first contact",""),IF(TODAY()>R5,"OVERDUE follow-up",IF(TODAY()=R5,"Follow up today",""))))))))
R6: =IF(OR(D6="",P6="",OR(O6="Contract signed + paid",O6="Closed – No response",O6="Lost"),N(Q6)>=Settings!$S$3),"",P6+Settings!$S$2) | X6: =IF(OR(D6="",B6=""),"",INT(TODAY()-B6)) | Y6: =IF(D6="","",IF(OR(COUNTIFS(Clients!$C$2:$C$501,D6,Clients!$S$2:$S$501,"Paid")>0,AND(H6<>"",COUNTIFS(Clients!$E$2:$E$501,H6,Clients!$S$2:$S$501,"Paid")>0)),"⚠ Refunded before – no free video",IF(OR(O6="Contract signed + paid",O6="Closed – No response",O6="Lost"),"",IF(O6="","Set a stage",IF(N(Q6)>=Settings!$S$3,"Close – 4 follow-ups sent",IF(R6="",IF(P6="","Make first contact",""),IF(TODAY()>R6,"OVERDUE follow-up",IF(TODAY()=R6,"Follow up today",""))))))))
R7: =IF(OR(D7="",P7="",OR(O7="Contract signed + paid",O7="Closed – No response",O7="Lost"),N(Q7)>=Settings!$S$3),"",P7+Settings!$S$2) | X7: =IF(OR(D7="",B7=""),"",INT(TODAY()-B7)) | Y7: =IF(D7="","",IF(OR(COUNTIFS(Clients!$C$2:$C$501,D7,Clients!$S$2:$S$501,"Paid")>0,AND(H7<>"",COUNTIFS(Clients!$E$2:$E$501,H7,Clients!$S$2:$S$501,"Paid")>0)),"⚠ Refunded before – no free video",IF(OR(O7="Contract signed + paid",O7="Closed – No response",O7="Lost"),"",IF(O7="","Set a stage",IF(N(Q7)>=Settings!$S$3,"Close – 4 follow-ups sent",IF(R7="",IF(P7="","Make first contact",""),IF(TODAY()>R7,"OVERDUE follow-up",IF(TODAY()=R7,"Follow up today",""))))))))
R8: =IF(OR(D8="",P8="",OR(O8="Contract signed + paid",O8="Closed – No response",O8="Lost"),N(Q8)>=Settings!$S$3),"",P8+Settings!$S$2) | X8: =IF(OR(D8="",B8=""),"",INT(TODAY()-B8)) | Y8: =IF(D8="","",IF(OR(COUNTIFS(Clients!$C$2:$C$501,D8,Clients!$S$2:$S$501,"Paid")>0,AND(H8<>"",COUNTIFS(Clients!$E$2:$E$501,H8,Clients!$S$2:$S$501,"Paid")>0)),"⚠ Refunded before – no free video",IF(OR(O8="Contract signed + paid",O8="Closed – No response",O8="Lost"),"",IF(O8="","Set a stage",IF(N(Q8)>=Settings!$S$3,"Close – 4 follow-ups sent",IF(R8="",IF(P8="","Make first contact",""),IF(TODAY()>R8,"OVERDUE follow-up",IF(TODAY()=R8,"Follow up today",""))))))))
R9: =IF(OR(D9="",P9="",OR(O9="Contract signed + paid",O9="Closed – No response",O9="Lost"),N(Q9)>=Settings!$S$3),"",P9+Settings!$S$2) | X9: =IF(OR(D9="",B9=""),"",INT(TODAY()-B9)) | Y9: =IF(D9="","",IF(OR(COUNTIFS(Clients!$C$2:$C$501,D9,Clients!$S$2:$S$501,"Paid")>0,AND(H9<>"",COUNTIFS(Clients!$E$2:$E$501,H9,Clients!$S$2:$S$501,"Paid")>0)),"⚠ Refunded before – no free video",IF(OR(O9="Contract signed + paid",O9="Closed – No response",O9="Lost"),"",IF(O9="","Set a stage",IF(N(Q9)>=Settings!$S$3,"Close – 4 follow-ups sent",IF(R9="",IF(P9="","Make first contact",""),IF(TODAY()>R9,"OVERDUE follow-up",IF(TODAY()=R9,"Follow up today",""))))))))
R10: =IF(OR(D10="",P10="",OR(O10="Contract signed + paid",O10="Closed – No response",O10="Lost"),N(Q10)>=Settings!$S$3),"",P10+Settings!$S$2) | X10: =IF(OR(D10="",B10=""),"",INT(TODAY()-B10)) | Y10: =IF(D10="","",IF(OR(COUNTIFS(Clients!$C$2:$C$501,D10,Clients!$S$2:$S$501,"Paid")>0,AND(H10<>"",COUNTIFS(Clients!$E$2:$E$501,H10,Clients!$S$2:$S$501,"Paid")>0)),"⚠ Refunded before – no free video",IF(OR(O10="Contract signed + paid",O10="Closed – No response",O10="Lost"),"",IF(O10="","Set a stage",IF(N(Q10)>=Settings!$S$3,"Close – 4 follow-ups sent",IF(R10="",IF(P10="","Make first contact",""),IF(TODAY()>R10,"OVERDUE follow-up",IF(TODAY()=R10,"Follow up today",""))))))))
R11: =IF(OR(D11="",P11="",OR(O11="Contract signed + paid",O11="Closed – No response",O11="Lost"),N(Q11)>=Settings!$S$3),"",P11+Settings!$S$2) | X11: =IF(OR(D11="",B11=""),"",INT(TODAY()-B11)) | Y11: =IF(D11="","",IF(OR(COUNTIFS(Clients!$C$2:$C$501,D11,Clients!$S$2:$S$501,"Paid")>0,AND(H11<>"",COUNTIFS(Clients!$E$2:$E$501,H11,Clients!$S$2:$S$501,"Paid")>0)),"⚠ Refunded before – no free video",IF(OR(O11="Contract signed + paid",O11="Closed – No response",O11="Lost"),"",IF(O11="","Set a stage",IF(N(Q11)>=Settings!$S$3,"Close – 4 follow-ups sent",IF(R11="",IF(P11="","Make first contact",""),IF(TODAY()>R11,"OVERDUE follow-up",IF(TODAY()=R11,"Follow up today",""))))))))
R12: =IF(OR(D12="",P12="",OR(O12="Contract signed + paid",O12="Closed – No response",O12="Lost"),N(Q12)>=Settings!$S$3),"",P12+Settings!$S$2) | X12: =IF(OR(D12="",B12=""),"",INT(TODAY()-B12)) | Y12: =IF(D12="","",IF(OR(COUNTIFS(Clients!$C$2:$C$501,D12,Clients!$S$2:$S$501,"Paid")>0,AND(H12<>"",COUNTIFS(Clients!$E$2:$E$501,H12,Clients!$S$2:$S$501,"Paid")>0)),"⚠ Refunded before – no free video",IF(OR(O12="Contract signed + paid",O12="Closed – No response",O12="Lost"),"",IF(O12="","Set a stage",IF(N(Q12)>=Settings!$S$3,"Close – 4 follow-ups sent",IF(R12="",IF(P12="","Make first contact",""),IF(TODAY()>R12,"OVERDUE follow-up",IF(TODAY()=R12,"Follow up today",""))))))))
R13: =IF(OR(D13="",P13="",OR(O13="Contract signed + paid",O13="Closed – No response",O13="Lost"),N(Q13)>=Settings!$S$3),"",P13+Settings!$S$2) | X13: =IF(OR(D13="",B13=""),"",INT(TODAY()-B13)) | Y13: =IF(D13="","",IF(OR(COUNTIFS(Clients!$C$2:$C$501,D13,Clients!$S$2:$S$501,"Paid")>0,AND(H13<>"",COUNTIFS(Clients!$E$2:$E$501,H13,Clients!$S$2:$S$501,"Paid")>0)),"⚠ Refunded before – no free video",IF(OR(O13="Contract signed + paid",O13="Closed – No response",O13="Lost"),"",IF(O13="","Set a stage",IF(N(Q13)>=Settings!$S$3,"Close – 4 follow-ups sent",IF(R13="",IF(P13="","Make first contact",""),IF(TODAY()>R13,"OVERDUE follow-up",IF(TODAY()=R13,"Follow up today",""))))))))
R14: =IF(OR(D14="",P14="",OR(O14="Contract signed + paid",O14="Closed – No response",O14="Lost"),N(Q14)>=Settings!$S$3),"",P14+Settings!$S$2) | X14: =IF(OR(D14="",B14=""),"",INT(TODAY()-B14)) | Y14: =IF(D14="","",IF(OR(COUNTIFS(Clients!$C$2:$C$501,D14,Clients!$S$2:$S$501,"Paid")>0,AND(H14<>"",COUNTIFS(Clients!$E$2:$E$501,H14,Clients!$S$2:$S$501,"Paid")>0)),"⚠ Refunded before – no free video",IF(OR(O14="Contract signed + paid",O14="Closed – No response",O14="Lost"),"",IF(O14="","Set a stage",IF(N(Q14)>=Settings!$S$3,"Close – 4 follow-ups sent",IF(R14="",IF(P14="","Make first contact",""),IF(TODAY()>R14,"OVERDUE follow-up",IF(TODAY()=R14,"Follow up today",""))))))))
... R501: =IF(OR(D501="",P501="",OR(O501="Contract signed + paid",O501="Closed – No response",O501="Lost"),N(Q501)>=Settings!$S$3),"",P501+Settings!$S$2) | X501: =IF(OR(D501="",B501=""),"",INT(TODAY()-B501)) | Y501: =IF(D501="","",IF(OR(COUNTIFS(Clients!$C$2:$C$501,D501,Clients!$S$2:$S$501,"Paid")>0,AND(H501<>"",COUNTIFS(Clients!$E$2:$E$501,H501,Clients!$S$2:$S$501,"Paid")>0)),"⚠ Refunded before – no free video",IF(OR(O501="Contract signed + paid",O501="Closed – No response",O501="Lost"),"",IF(O501="","Set a stage",IF(N(Q501)>=Settings!$S$3,"Close – 4 follow-ups sent",IF(R501="",IF(P501="","Make first contact",""),IF(TODAY()>R501,"OVERDUE follow-up",IF(TODAY()=R501,"Follow up today",""))))))))

Sheet Clients
A1: Client ID | B1: Lead ID | C1: Business name | D1: Contact name | E1: Phone / WhatsApp | F1: Email | G1: Instagram | H1: Package | I1: Monthly fee (AED) | J1: Contract signed date 📅 | K1: Amount paid (AED) | L1: Payment method | M1: Free video shoot date 📅 | N1: Free video delivered 📅 | O1: Decision deadline | P1: Client decision | Q1: Status | R1: Back-out reason | S1: Refund status | T1: Refund amount (AED) | U1: Refund date 📅 | V1: Plan start date 📅 | W1: Minimum term ends | X1: Account manager | Y1: Videographer | Z1: Notes
A2: CL-0001 | B2: IN-0001 | C2: Example Salon (EXAMPLE) | D2: Layla K. | E2: +971 52 000 0000 | F2: layla@example.com | G2: @examplesalon | H2: Growth | I2: =IF(H2="","",IFERROR(INDEX(Settings!$G$2:$G$4,MATCH(H2,Settings!$F$2:$F$4,0)),"")) -> 7500 | J2: 46307 | K2: 7875 | L2: Bank transfer | M2: 46309 | N2: 46314 | O2: =IF(N2="","",WORKDAY(N2,Settings!$S$4)) -> 46317 | P2: Pending | Q2: =IF(C2="","",IF(P2="Backed out",IF(S2="Paid","Refunded – closed",IF(R2="","Refund – log reason first","Refund in progress")),IF(K2="","Awaiting payment",IF(N2="",IF(M2="","Schedule free video","Free video in production"),IF(P2="Approved","Active",IF(TODAY()>O2,"Active – plan went ahead","Decision pending – "&NETWORKDAYS(TODAY(),O2)&" working day(s) left")))))) -> Decision pending – 3 working day(s) left | W2: =IF(V2="","",EDATE(V2,Settings!$S$6)) | X2: Lianna | Y2: Azeem | Z2: Example row – overwrite or delete. Paid = AED 7,500 + 5% VAT.
I3: =IF(H3="","",IFERROR(INDEX(Settings!$G$2:$G$4,MATCH(H3,Settings!$F$2:$F$4,0)),"")) | O3: =IF(N3="","",WORKDAY(N3,Settings!$S$4)) | Q3: =IF(C3="","",IF(P3="Backed out",IF(S3="Paid","Refunded – closed",IF(R3="","Refund – log reason first","Refund in progress")),IF(K3="","Awaiting payment",IF(N3="",IF(M3="","Schedule free video","Free video in production"),IF(P3="Approved","Active",IF(TODAY()>O3,"Active – plan went ahead","Decision pending – "&NETWORKDAYS(TODAY(),O3)&" working day(s) left")))))) | W3: =IF(V3="","",EDATE(V3,Settings!$S$6))
I4: =IF(H4="","",IFERROR(INDEX(Settings!$G$2:$G$4,MATCH(H4,Settings!$F$2:$F$4,0)),"")) | O4: =IF(N4="","",WORKDAY(N4,Settings!$S$4)) | Q4: =IF(C4="","",IF(P4="Backed out",IF(S4="Paid","Refunded – closed",IF(R4="","Refund – log reason first","Refund in progress")),IF(K4="","Awaiting payment",IF(N4="",IF(M4="","Schedule free video","Free video in production"),IF(P4="Approved","Active",IF(TODAY()>O4,"Active – plan went ahead","Decision pending – "&NETWORKDAYS(TODAY(),O4)&" working day(s) left")))))) | W4: =IF(V4="","",EDATE(V4,Settings!$S$6))
I5: =IF(H5="","",IFERROR(INDEX(Settings!$G$2:$G$4,MATCH(H5,Settings!$F$2:$F$4,0)),"")) | O5: =IF(N5="","",WORKDAY(N5,Settings!$S$4)) | Q5: =IF(C5="","",IF(P5="Backed out",IF(S5="Paid","Refunded – closed",IF(R5="","Refund – log reason first","Refund in progress")),IF(K5="","Awaiting payment",IF(N5="",IF(M5="","Schedule free video","Free video in production"),IF(P5="Approved","Active",IF(TODAY()>O5,"Active – plan went ahead","Decision pending – "&NETWORKDAYS(TODAY(),O5)&" working day(s) left")))))) | W5: =IF(V5="","",EDATE(V5,Settings!$S$6))
I6: =IF(H6="","",IFERROR(INDEX(Settings!$G$2:$G$4,MATCH(H6,Settings!$F$2:$F$4,0)),"")) | O6: =IF(N6="","",WORKDAY(N6,Settings!$S$4)) | Q6: =IF(C6="","",IF(P6="Backed out",IF(S6="Paid","Refunded – closed",IF(R6="","Refund – log reason first","Refund in progress")),IF(K6="","Awaiting payment",IF(N6="",IF(M6="","Schedule free video","Free video in production"),IF(P6="Approved","Active",IF(TODAY()>O6,"Active – plan went ahead","Decision pending – "&NETWORKDAYS(TODAY(),O6)&" working day(s) left")))))) | W6: =IF(V6="","",EDATE(V6,Settings!$S$6))
I7: =IF(H7="","",IFERROR(INDEX(Settings!$G$2:$G$4,MATCH(H7,Settings!$F$2:$F$4,0)),"")) | O7: =IF(N7="","",WORKDAY(N7,Settings!$S$4)) | Q7: =IF(C7="","",IF(P7="Backed out",IF(S7="Paid","Refunded – closed",IF(R7="","Refund – log reason first","Refund in progress")),IF(K7="","Awaiting payment",IF(N7="",IF(M7="","Schedule free video","Free video in production"),IF(P7="Approved","Active",IF(TODAY()>O7,"Active – plan went ahead","Decision pending – "&NETWORKDAYS(TODAY(),O7)&" working day(s) left")))))) | W7: =IF(V7="","",EDATE(V7,Settings!$S$6))
I8: =IF(H8="","",IFERROR(INDEX(Settings!$G$2:$G$4,MATCH(H8,Settings!$F$2:$F$4,0)),"")) | O8: =IF(N8="","",WORKDAY(N8,Settings!$S$4)) | Q8: =IF(C8="","",IF(P8="Backed out",IF(S8="Paid","Refunded – closed",IF(R8="","Refund – log reason first","Refund in progress")),IF(K8="","Awaiting payment",IF(N8="",IF(M8="","Schedule free video","Free video in production"),IF(P8="Approved","Active",IF(TODAY()>O8,"Active – plan went ahead","Decision pending – "&NETWORKDAYS(TODAY(),O8)&" working day(s) left")))))) | W8: =IF(V8="","",EDATE(V8,Settings!$S$6))
I9: =IF(H9="","",IFERROR(INDEX(Settings!$G$2:$G$4,MATCH(H9,Settings!$F$2:$F$4,0)),"")) | O9: =IF(N9="","",WORKDAY(N9,Settings!$S$4)) | Q9: =IF(C9="","",IF(P9="Backed out",IF(S9="Paid","Refunded – closed",IF(R9="","Refund – log reason first","Refund in progress")),IF(K9="","Awaiting payment",IF(N9="",IF(M9="","Schedule free video","Free video in production"),IF(P9="Approved","Active",IF(TODAY()>O9,"Active – plan went ahead","Decision pending – "&NETWORKDAYS(TODAY(),O9)&" working day(s) left")))))) | W9: =IF(V9="","",EDATE(V9,Settings!$S$6))
I10: =IF(H10="","",IFERROR(INDEX(Settings!$G$2:$G$4,MATCH(H10,Settings!$F$2:$F$4,0)),"")) | O10: =IF(N10="","",WORKDAY(N10,Settings!$S$4)) | Q10: =IF(C10="","",IF(P10="Backed out",IF(S10="Paid","Refunded – closed",IF(R10="","Refund – log reason first","Refund in progress")),IF(K10="","Awaiting payment",IF(N10="",IF(M10="","Schedule free video","Free video in production"),IF(P10="Approved","Active",IF(TODAY()>O10,"Active – plan went ahead","Decision pending – "&NETWORKDAYS(TODAY(),O10)&" working day(s) left")))))) | W10: =IF(V10="","",EDATE(V10,Settings!$S$6))
I11: =IF(H11="","",IFERROR(INDEX(Settings!$G$2:$G$4,MATCH(H11,Settings!$F$2:$F$4,0)),"")) | O11: =IF(N11="","",WORKDAY(N11,Settings!$S$4)) | Q11: =IF(C11="","",IF(P11="Backed out",IF(S11="Paid","Refunded – closed",IF(R11="","Refund – log reason first","Refund in progress")),IF(K11="","Awaiting payment",IF(N11="",IF(M11="","Schedule free video","Free video in production"),IF(P11="Approved","Active",IF(TODAY()>O11,"Active – plan went ahead","Decision pending – "&NETWORKDAYS(TODAY(),O11)&" working day(s) left")))))) | W11: =IF(V11="","",EDATE(V11,Settings!$S$6))
I12: =IF(H12="","",IFERROR(INDEX(Settings!$G$2:$G$4,MATCH(H12,Settings!$F$2:$F$4,0)),"")) | O12: =IF(N12="","",WORKDAY(N12,Settings!$S$4)) | Q12: =IF(C12="","",IF(P12="Backed out",IF(S12="Paid","Refunded – closed",IF(R12="","Refund – log reason first","Refund in progress")),IF(K12="","Awaiting payment",IF(N12="",IF(M12="","Schedule free video","Free video in production"),IF(P12="Approved","Active",IF(TODAY()>O12,"Active – plan went ahead","Decision pending – "&NETWORKDAYS(TODAY(),O12)&" working day(s) left")))))) | W12: =IF(V12="","",EDATE(V12,Settings!$S$6))
I13: =IF(H13="","",IFERROR(INDEX(Settings!$G$2:$G$4,MATCH(H13,Settings!$F$2:$F$4,0)),"")) | O13: =IF(N13="","",WORKDAY(N13,Settings!$S$4)) | Q13: =IF(C13="","",IF(P13="Backed out",IF(S13="Paid","Refunded – closed",IF(R13="","Refund – log reason first","Refund in progress")),IF(K13="","Awaiting payment",IF(N13="",IF(M13="","Schedule free video","Free video in production"),IF(P13="Approved","Active",IF(TODAY()>O13,"Active – plan went ahead","Decision pending – "&NETWORKDAYS(TODAY(),O13)&" working day(s) left")))))) | W13: =IF(V13="","",EDATE(V13,Settings!$S$6))
I14: =IF(H14="","",IFERROR(INDEX(Settings!$G$2:$G$4,MATCH(H14,Settings!$F$2:$F$4,0)),"")) | O14: =IF(N14="","",WORKDAY(N14,Settings!$S$4)) | Q14: =IF(C14="","",IF(P14="Backed out",IF(S14="Paid","Refunded – closed",IF(R14="","Refund – log reason first","Refund in progress")),IF(K14="","Awaiting payment",IF(N14="",IF(M14="","Schedule free video","Free video in production"),IF(P14="Approved","Active",IF(TODAY()>O14,"Active – plan went ahead","Decision pending – "&NETWORKDAYS(TODAY(),O14)&" working day(s) left")))))) | W14: =IF(V14="","",EDATE(V14,Settings!$S$6))
... I501: =IF(H501="","",IFERROR(INDEX(Settings!$G$2:$G$4,MATCH(H501,Settings!$F$2:$F$4,0)),"")) | O501: =IF(N501="","",WORKDAY(N501,Settings!$S$4)) | Q501: =IF(C501="","",IF(P501="Backed out",IF(S501="Paid","Refunded – closed",IF(R501="","Refund – log reason first","Refund in progress")),IF(K501="","Awaiting payment",IF(N501="",IF(M501="","Schedule free video","Free video in production"),IF(P501="Approved","Active",IF(TODAY()>O501,"Active – plan went ahead","Decision pending – "&NETWORKDAYS(TODAY(),O501)&" working day(s) left")))))) | W501: =IF(V501="","",EDATE(V501,Settings!$S$6))

Sheet Shoots
A1: Shoot ID | B1: Client ID | C1: Business name | D1: Shoot type | E1: Shoot date 📅 | F1: Time | G1: Location | H1: Videographer | I1: Status | J1: Delivered date 📅 | K1: Revision rounds used | L1: Video link | M1: Notes | N1: Flag
A2: SH-0001 | B2: CL-0001 | C2: =IF(B2="","",IFERROR(INDEX(Clients!$C$2:$C$501,MATCH(B2,Clients!$A$2:$A$501,0)),"Client ID not found")) -> Example Salon (EXAMPLE) | D2: Free video | E2: 46309 | F2: 0.41666667 | G2: Client salon, Jumeirah | H2: Azeem | I2: Delivered | J2: 46314 | K2: 1 | M2: Example row – overwrite or delete. | N2: =IF(A2="","",IF(N(K2)>Settings!$S$7,"Over revision limit",IF(AND(D2="Free video",J2="",E2<>"",TODAY()>WORKDAY(E2,Settings!$S$5)),"LATE – free video promised in 5 working days",IF(AND(E2<>"",E2=TODAY()),"Shooting today",""))))
C3: =IF(B3="","",IFERROR(INDEX(Clients!$C$2:$C$501,MATCH(B3,Clients!$A$2:$A$501,0)),"Client ID not found")) | N3: =IF(A3="","",IF(N(K3)>Settings!$S$7,"Over revision limit",IF(AND(D3="Free video",J3="",E3<>"",TODAY()>WORKDAY(E3,Settings!$S$5)),"LATE – free video promised in 5 working days",IF(AND(E3<>"",E3=TODAY()),"Shooting today",""))))
C4: =IF(B4="","",IFERROR(INDEX(Clients!$C$2:$C$501,MATCH(B4,Clients!$A$2:$A$501,0)),"Client ID not found")) | N4: =IF(A4="","",IF(N(K4)>Settings!$S$7,"Over revision limit",IF(AND(D4="Free video",J4="",E4<>"",TODAY()>WORKDAY(E4,Settings!$S$5)),"LATE – free video promised in 5 working days",IF(AND(E4<>"",E4=TODAY()),"Shooting today",""))))
C5: =IF(B5="","",IFERROR(INDEX(Clients!$C$2:$C$501,MATCH(B5,Clients!$A$2:$A$501,0)),"Client ID not found")) | N5: =IF(A5="","",IF(N(K5)>Settings!$S$7,"Over revision limit",IF(AND(D5="Free video",J5="",E5<>"",TODAY()>WORKDAY(E5,Settings!$S$5)),"LATE – free video promised in 5 working days",IF(AND(E5<>"",E5=TODAY()),"Shooting today",""))))
C6: =IF(B6="","",IFERROR(INDEX(Clients!$C$2:$C$501,MATCH(B6,Clients!$A$2:$A$501,0)),"Client ID not found")) | N6: =IF(A6="","",IF(N(K6)>Settings!$S$7,"Over revision limit",IF(AND(D6="Free video",J6="",E6<>"",TODAY()>WORKDAY(E6,Settings!$S$5)),"LATE – free video promised in 5 working days",IF(AND(E6<>"",E6=TODAY()),"Shooting today",""))))
C7: =IF(B7="","",IFERROR(INDEX(Clients!$C$2:$C$501,MATCH(B7,Clients!$A$2:$A$501,0)),"Client ID not found")) | N7: =IF(A7="","",IF(N(K7)>Settings!$S$7,"Over revision limit",IF(AND(D7="Free video",J7="",E7<>"",TODAY()>WORKDAY(E7,Settings!$S$5)),"LATE – free video promised in 5 working days",IF(AND(E7<>"",E7=TODAY()),"Shooting today",""))))
C8: =IF(B8="","",IFERROR(INDEX(Clients!$C$2:$C$501,MATCH(B8,Clients!$A$2:$A$501,0)),"Client ID not found")) | N8: =IF(A8="","",IF(N(K8)>Settings!$S$7,"Over revision limit",IF(AND(D8="Free video",J8="",E8<>"",TODAY()>WORKDAY(E8,Settings!$S$5)),"LATE – free video promised in 5 working days",IF(AND(E8<>"",E8=TODAY()),"Shooting today",""))))
C9: =IF(B9="","",IFERROR(INDEX(Clients!$C$2:$C$501,MATCH(B9,Clients!$A$2:$A$501,0)),"Client ID not found")) | N9: =IF(A9="","",IF(N(K9)>Settings!$S$7,"Over revision limit",IF(AND(D9="Free video",J9="",E9<>"",TODAY()>WORKDAY(E9,Settings!$S$5)),"LATE – free video promised in 5 working days",IF(AND(E9<>"",E9=TODAY()),"Shooting today",""))))
C10: =IF(B10="","",IFERROR(INDEX(Clients!$C$2:$C$501,MATCH(B10,Clients!$A$2:$A$501,0)),"Client ID not found")) | N10: =IF(A10="","",IF(N(K10)>Settings!$S$7,"Over revision limit",IF(AND(D10="Free video",J10="",E10<>"",TODAY()>WORKDAY(E10,Settings!$S$5)),"LATE – free video promised in 5 working days",IF(AND(E10<>"",E10=TODAY()),"Shooting today",""))))
C11: =IF(B11="","",IFERROR(INDEX(Clients!$C$2:$C$501,MATCH(B11,Clients!$A$2:$A$501,0)),"Client ID not found")) | N11: =IF(A11="","",IF(N(K11)>Settings!$S$7,"Over revision limit",IF(AND(D11="Free video",J11="",E11<>"",TODAY()>WORKDAY(E11,Settings!$S$5)),"LATE – free video promised in 5 working days",IF(AND(E11<>"",E11=TODAY()),"Shooting today",""))))
C12: =IF(B12="","",IFERROR(INDEX(Clients!$C$2:$C$501,MATCH(B12,Clients!$A$2:$A$501,0)),"Client ID not found")) | N12: =IF(A12="","",IF(N(K12)>Settings!$S$7,"Over revision limit",IF(AND(D12="Free video",J12="",E12<>"",TODAY()>WORKDAY(E12,Settings!$S$5)),"LATE – free video promised in 5 working days",IF(AND(E12<>"",E12=TODAY()),"Shooting today",""))))
C13: =IF(B13="","",IFERROR(INDEX(Clients!$C$2:$C$501,MATCH(B13,Clients!$A$2:$A$501,0)),"Client ID not found")) | N13: =IF(A13="","",IF(N(K13)>Settings!$S$7,"Over revision limit",IF(AND(D13="Free video",J13="",E13<>"",TODAY()>WORKDAY(E13,Settings!$S$5)),"LATE – free video promised in 5 working days",IF(AND(E13<>"",E13=TODAY()),"Shooting today",""))))
C14: =IF(B14="","",IFERROR(INDEX(Clients!$C$2:$C$501,MATCH(B14,Clients!$A$2:$A$501,0)),"Client ID not found")) | N14: =IF(A14="","",IF(N(K14)>Settings!$S$7,"Over revision limit",IF(AND(D14="Free video",J14="",E14<>"",TODAY()>WORKDAY(E14,Settings!$S$5)),"LATE – free video promised in 5 working days",IF(AND(E14<>"",E14=TODAY()),"Shooting today",""))))
... C501: =IF(B501="","",IFERROR(INDEX(Clients!$C$2:$C$501,MATCH(B501,Clients!$A$2:$A$501,0)),"Client ID not found")) | N501: =IF(A501="","",IF(N(K501)>Settings!$S$7,"Over revision limit",IF(AND(D501="Free video",J501="",E501<>"",TODAY()>WORKDAY(E501,Settings!$S$5)),"LATE – free video promised in 5 working days",IF(AND(E501<>"",E501=TODAY()),"Shooting today",""))))

Sheet Automations
A1: # | B1: When this happens… | C1: App | D1: …this happens automatically | E1: Writes to (tab → columns) | F1: Phase
A2: 1 | B2: Website form submitted | C2: yontro.ae → Make.com | D2: Add row, Source = Website form, Stage = New; alert Usama on WhatsApp | E2: Inbound → Lead ID, Date received, Time received, Source, Business, Contact, Phone, Instagram, Wants more of | F2: 1
A3: 2 | B3: Calendly meeting booked | C3: Calendly → Make.com | D3: Find lead by email/phone; set Stage = Meeting booked, Meeting date and Meeting time; reminder 24h before | E3: Inbound / Outbound → Stage, Meeting date, Meeting time | F3: 1
A4: 3 | B4: Prospects saved to an Apollo list | C4: Apollo → Make.com | D4: Add rows, skip duplicates by email or phone; Stage = New | E4: Outbound → Lead ID, Date added, Source, Business…Apollo list | F4: 1
A5: 4 | B5: Prospect replies to an Apollo sequence | C5: Apollo → Make.com | D5: Set Stage = Replied; Last contact date = today | E5: Outbound → Stage, Last contact date | F5: 1
A6: 5 | B6: Stage set to Contract signed + paid | C6: Sheets → Make.com | D6: Create Clients row and a Free video row in Shoots; send Lianna the onboarding checklist | E6: Clients → Client ID…Amount paid; Shoots → Shoot ID, Client ID, Shoot type | F6: 1
A7: 6 | B7: Shoot date entered | C7: Sheets → Google Calendar | D7: Create event on Azeem's calendar with location; reminder to client the day before | E7: (calendar only) | F7: 1
A8: 7 | B8: Free video delivered | C8: Sheets → Make.com | D8: Decision window starts; Lianna nudged halfway; Usama alerted on deadline day | E8: (reads Clients → Free video delivered, Decision deadline) | F8: 2
A9: 8 | B9: WhatsApp message from a new number | C9: WhatsApp Business API (e.g. Wati) → Make.com | D9: Add row, Source = WhatsApp; auto-reply with Calendly meeting link | E9: Inbound → Date received, Source, Phone, Stage | F9: 2
A10: 9 | B10: Instagram DM or comment keyword | C10: ManyChat → Make.com | D10: Add row, Source = Instagram DM; reply with meeting link | E10: Inbound → Date received, Source, Instagram, Stage | F10: 3
A11: 10 | B11: Every morning 8:00 | C11: Apps Script / Make.com | D11: Message each owner their 'Follow up today' and 'OVERDUE' rows | E11: (reads Action flag) | F11: 2
A13: Rules that keep it clean
A14: • Each column has ONE writer: an app or a person, never both. Grey columns are formulas – nobody types there.
A15: • Every lead gets a Lead ID (IN-0001 / OUT-0001). Phone or email is the duplicate check.
A16: • Phase 1 = website form, Calendly, Apollo, Clients, Calendar. Add WhatsApp and Instagram once phase 1 runs smoothly.

Sheet Settings
A1: Lead stages | B1: Inbound sources | C1: Outbound sources | D1: Industries | E1: Team | F1: Package | G1: Monthly fee (AED, ex VAT) | H1: Videos / month | I1: Payment methods | J1: Client decision | K1: Back-out reasons | L1: Refund status | M1: Shoot types | N1: Shoot status | O1: Lost / closed reasons | P1: Wants more of | Q1: Shoot times | R1: Rule | S1: Value | W1: Times (all day)
A2: New | B2: Website form | C2: Apollo | D2: Hospitality / F&B | E2: Usama | F2: Launch | G2: 5000 | H2: 10 | I2: Bank transfer | J2: Pending | K2: Video style | L2: Requested | M2: Free video | N2: Scheduled | O2: No response (4 follow-ups) | P2: Walk-in customers | Q2: 0.33333333 | R2: Follow-up gap (days) | S2: 3 | T2: Your rule: follow up every 3 days after a lead goes quiet. | W2: 0
A3: Contacted | B3: WhatsApp | C3: LinkedIn | D3: Retail | E3: Lianna | F3: Growth | G3: 7500 | H3: 15 | I3: Card | J3: Approved | K3: Price | L3: Approved | M3: Plan shoot | N3: Shot | O3: Price | P3: Enquiries and bookings | Q3: 0.35416667 | R3: Max follow-ups before closing | S3: 4 | T3: Your rule: 4 follow-ups, each with new value, then stop outreach. | W3: 0.020833333
A4: Replied | B4: Instagram DM | C4: Google Maps | D4: Real estate | E4: Azeem | F4: Scale | G4: 10000 | H4: 20 | I4: Cheque | J4: Backed out | K4: Timing | L4: Paid | M4: Add-on | N4: Editing | O4: Not ready | P4: Online sales | Q4: 0.375 | R4: Decision window after free video (working days) | S4: 3 | T4: NOT DECIDED YET - placeholder of 3 working days. Change this one cell and every deadline updates. | W4: 0.041666667
A5: Meeting booked | B5: Referral | C5: Instagram research | D5: Entertainment | E5: Owner | I5: Cash | K5: Changed mind | M5: Event coverage | N5: Sent for approval | O5: Went with competitor | P5: Followers and reach | Q5: 0.39583333 | R5: Free video delivery promise (working days) | S5: 5 | T5: From the website: delivered within five working days. | W5: 0.0625
A6: Meeting held | B6: Walk-in | C6: Event / networking | D6: Fitness / wellness | F6: Source: yontro.ae Packages section. Prices exclude 5% VAT. | I6: Payment link | K6: Business issue | N6: Delivered | O6: In-house team | P6: A better-looking brand | Q6: 0.41666667 | R6: Minimum term (months) | S6: 3 | T6: From the website: three-month minimum, then month to month. | W6: 0.083333333
A7: Proposal sent | B7: Phone call | C7: Other | D7: Beauty / salon | K7: Other | N7: Posted | O7: Not a fit | Q7: 0.4375 | R7: Max revision rounds per video | S7: 2 | T7: From the website FAQ: two rounds of changes included. | W7: 0.10416667
A8: Contract signed + paid | B8: Other | D8: Clinic / healthcare | O8: Other | Q8: 0.45833333 | W8: 0.125
A9: Closed – No response | D9: Education | Q9: 0.47916667 | W9: 0.14583333
A10: Lost | D10: Automotive | Q10: 0.5 | W10: 0.16666667
D11: Other | Q11: 0.52083333 | W11: 0.1875
Q12: 0.54166667 | W12: 0.20833333
Q13: 0.5625 | W13: 0.22916667
Q14: 0.58333333 | W14: 0.25
Q15: 0.60416667 | W15: 0.27083333
Q16: 0.625 | W16: 0.29166667
Q17: 0.64583333 | W17: 0.3125
Q18: 0.66666667 | W18: 0.33333333
Q19: 0.6875 | W19: 0.35416667
Q20: 0.70833333 | W20: 0.375
Q21: 0.72916667 | W21: 0.39583333
Q22: 0.75 | W22: 0.41666667
Q23: 0.77083333 | W23: 0.4375
... Q26: 0.83333333 | W26: 0.5
W27: 0.52083333
W28: 0.54166667
W29: 0.5625
W30: 0.58333333
W31: 0.60416667
W32: 0.625
W33: 0.64583333
W34: 0.66666667
W35: 0.6875
W36: 0.70833333
W37: 0.72916667
W38: 0.75
... W49: 0.97916667
